Workbook

Sheet Raw Data ---->

Sheet Round 1 Data
B2: Scotland | C2: Win | E2: Wales | F2: 10 | G2: 34 | H2: Ireland
B3: Wales | C3: Loss | E3: England | F3: 23 | G3: 29 | H3: Scotland
B4: Ireland | C4: Win | E4: Italy | F4: 24 | G4: 29 | H4: France
B5: England | C5: Loss
B6: France | C6: Win
B7: Italy | C7: Loss
A9: Name | B9: Nation | C9: Position | D9: Win/Loss | E9: Time Played | F9: Tackles | G9: Dominant Tackles | H9: Line Breaks | I9: Metres Carried | J9: 50-22 | K9: Lineout Steal | L9: Breakdown Steal | M9: Try | N9: Assists | O9: Conversion | P9: Penalty | Q9: Drop Goal | R9: Yellow Card | S9: Red Card | T9: Game Total | U9: MoM
A10: J. Adams | B10: {=_xlfn.XLOOKUP(A10,'Player List'!$A$2:$A$177,'Player List'!$B$2:$C$177)} -> Wales | C10: Back Three | D10: =_xlfn.XLOOKUP(B10,$B$2:$B$7,$C$2:$C$7) -> Loss | E10: 80 | F10: 3 | G10: 3 | I10: 36 | T10: 31.2
A11: A. Cuthbert | B11: {=_xlfn.XLOOKUP(A11,'Player List'!$A$2:$A$177,'Player List'!$B$2:$C$177)} -> Wales | C11: Back Three | D11: =_xlfn.XLOOKUP(B11,$B$2:$B$7,$C$2:$C$7) -> Loss | E11: 12 | F11: 1 | I11: 28 | T11: 6.6
A12: R. Dyer | B12: {=_xlfn.XLOOKUP(A12,'Player List'!$A$2:$A$177,'Player List'!$B$2:$C$177)} -> Wales | C12: Back Three | D12: =_xlfn.XLOOKUP(B12,$B$2:$B$7,$C$2:$C$7) -> Loss | E12: 68 | F12: 4 | H12: 2 | I12: 107 | T12: 39.4
A13: L. Williams | B13: {=_xlfn.XLOOKUP(A13,'Player List'!$A$2:$A$177,'Player List'!$B$2:$C$177)} -> Wales | C13: Back Three | D13: =_xlfn.XLOOKUP(B13,$B$2:$B$7,$C$2:$C$7) -> Loss | E13: 70 | F13: 2 | H13: 2 | I13: 108 | L13: 1 | M13: 1 | R13: 1 | T13: 54.6
A14: J. Hawkins | B14: {=_xlfn.XLOOKUP(A14,'Player List'!$A$2:$A$177,'Player List'!$B$2:$C$177)} -> Wales | C14: Centre | D14: =_xlfn.XLOOKUP(B14,$B$2:$B$7,$C$2:$C$7) -> Loss | E14: 80 | F14: 6 | G14: 1 | H14: 1 | I14: 75 | T14: 35
A15: G. North | B15: {=_xlfn.XLOOKUP(A15,'Player List'!$A$2:$A$177,'Player List'!$B$2:$C$177)} -> Wales | C15: Centre | D15: =_xlfn.XLOOKUP(B15,$B$2:$B$7,$C$2:$C$7) -> Loss | E15: 80 | F15: 4 | I15: 58 | T15: 15.6
A16: D. Biggar | B16: {=_xlfn.XLOOKUP(A16,'Player List'!$A$2:$A$177,'Player List'!$B$2:$C$177)} -> Wales | C16: Fly Half | D16: =_xlfn.XLOOKUP(B16,$B$2:$B$7,$C$2:$C$7) -> Loss | E16: 67 | F16: 9 | H16: 1 | I16: 35 | N16: 1 | O16: 1 | P16: 1 | T16: 37
A17: O. Williams | B17: {=_xlfn.XLOOKUP(A17,'Player List'!$A$2:$A$177,'Player List'!$B$2:$C$177)} -> Wales | C17: Fly Half | D17: =_xlfn.XLOOKUP(B17,$B$2:$B$7,$C$2:$C$7) -> Loss | E17: 13 | F17: 1 | I17: 4 | T17: 1.8
A18: R. Webb | B18: {=_xlfn.XLOOKUP(A18,'Player List'!$A$2:$A$177,'Player List'!$B$2:$C$177)} -> Wales | C18: Scrum Half | D18: =_xlfn.XLOOKUP(B18,$B$2:$B$7,$C$2:$C$7) -> Loss | E18: 17 | F18: 2 | G18: 1 | I18: 1 | T18: 9.2
A19: T. Williams | B19: {=_xlfn.XLOOKUP(A19,'Player List'!$A$2:$A$177,'Player List'!$B$2:$C$177)} -> Wales | C19: Scrum Half | D19: =_xlfn.XLOOKUP(B19,$B$2:$B$7,$C$2:$C$7) -> Loss | E19: 63 | F19: 6 | I19: 19 | T19: 9.8
A20: T. Faletau | B20: {=_xlfn.XLOOKUP(A20,'Player List'!$A$2:$A$177,'Player List'!$B$2:$C$177)} -> Wales | C20: Back Row | D20: =_xlfn.XLOOKUP(B20,$B$2:$B$7,$C$2:$C$7) -> Loss | E20: 80 | F20: 20 | G20: 1 | I20: 49 | T20: 36.8
A21: J. Morgan | B21: {=_xlfn.XLOOKUP(A21,'Player List'!$A$2:$A$177,'Player List'!$B$2:$C$177)} -> Wales | C21: Back Row | D21: =_xlfn.XLOOKUP(B21,$B$2:$B$7,$C$2:$C$7) -> Loss | E21: 80 | F21: 14 | G21: 3 | I21: 43 | L21: 1 | T21: 50.6
A22: T. Reffell | B22: {=_xlfn.XLOOKUP(A22,'Player List'!$A$2:$A$177,'Player List'!$B$2:$C$177)} -> Wales | C22: Back Row | D22: =_xlfn.XLOOKUP(B22,$B$2:$B$7,$C$2:$C$7) -> Loss | E22: 26 | F22: 8 | T22: 8
A23: J. Tipuric | B23: {=_xlfn.XLOOKUP(A23,'Player List'!$A$2:$A$177,'Player List'!$B$2:$C$177)} -> Wales | C23: Back Row | D23: =_xlfn.XLOOKUP(B23,$B$2:$B$7,$C$2:$C$7) -> Loss | E23: 54 | F23: 11 | G23: 3 | I23: 18 | T23: 35.6
A24: A. Beard | B24: {=_xlfn.XLOOKUP(A24,'Player List'!$A$2:$A$177,'Player List'!$B$2:$C$177)} -> Wales | C24: Second Row | D24: =_xlfn.XLOOKUP(B24,$B$2:$B$7,$C$2:$C$7) -> Loss | E24: 80 | F24: 13 | G24: 2 | I24: 7 | T24: 28.4
A25: D. Jenkins | B25: {=_xlfn.XLOOKUP(A25,'Player List'!$A$2:$A$177,'Player List'!$B$2:$C$177)} -> Wales | C25: Second Row | D25: =_xlfn.XLOOKUP(B25,$B$2:$B$7,$C$2:$C$7) -> Loss | E25: 19 | F25: 3 | I25: 35 | T25: 10
A26: A. Jones | B26: {=_xlfn.XLOOKUP(A26,'Player List'!$A$2:$A$177,'Player List'!$B$2:$C$177)} -> Wales | C26: Second Row | D26: =_xlfn.XLOOKUP(B26,$B$2:$B$7,$C$2:$C$7) -> Loss | E26: 61 | F26: 10 | G26: 1 | I26: 29 | T26: 22.8
A27: R. Carre | B27: {=_xlfn.XLOOKUP(A27,'Player List'!$A$2:$A$177,'Player List'!$B$2:$C$177)} -> Wales | C27: Prop | D27: =_xlfn.XLOOKUP(B27,$B$2:$B$7,$C$2:$C$7) -> Loss | E27: 26 | F27: 3 | L27: 1 | T27: 10
A28: T. Francis | B28: {=_xlfn.XLOOKUP(A28,'Player List'!$A$2:$A$177,'Player List'!$B$2:$C$177)} -> Wales | C28: Prop | D28: =_xlfn.XLOOKUP(B28,$B$2:$B$7,$C$2:$C$7) -> Loss | E28: 40 | F28: 9 | G28: 3 | T28: 30
A29: D. Lewis | B29: {=_xlfn.XLOOKUP(A29,'Player List'!$A$2:$A$177,'Player List'!$B$2:$C$177)} -> Wales | C29: Prop | D29: =_xlfn.XLOOKUP(B29,$B$2:$B$7,$C$2:$C$7) -> Loss | E29: 40 | F29: 5 | I29: 7 | T29: 6.4
A30: G. Thomas | B30: {=_xlfn.XLOOKUP(A30,'Player List'!$A$2:$A$177,'Player List'!$B$2:$C$177)} -> Wales | C30: Prop | D30: =_xlfn.XLOOKUP(B30,$B$2:$B$7,$C$2:$C$7) -> Loss | E30: 54 | F30: 11 | G30: 2 | I30: 21 | T30: 29.2
A31: S. Baldwin | B31: {=_xlfn.XLOOKUP(A31,'Player List'!$A$2:$A$177,'Player List'!$B$2:$C$177)} -> Wales | C31: Hooker | D31: =_xlfn.XLOOKUP(B31,$B$2:$B$7,$C$2:$C$7) -> Loss | E31: 19 | F31: 2 | I31: 19 | T31: 5.8
A32: K. Owens | B32: {=_xlfn.XLOOKUP(A32,'Player List'!$A$2:$A$177,'Player List'!$B$2:$C$177)} -> Wales | C32: Hooker | D32: =_xlfn.XLOOKUP(B32,$B$2:$B$7,$C$2:$C$7) -> Loss | E32: 61 | F32: 12 | G32: 3 | I32: 38 | T32: 40.6
A33: M. Hansen | B33: {=_xlfn.XLOOKUP(A33,'Player List'!$A$2:$A$177,'Player List'!$B$2:$C$177)} -> Ireland | C33: Back Three | D33: =_xlfn.XLOOKUP(B33,$B$2:$B$7,$C$2:$C$7) -> Win | E33: 80 | F33: 5 | G33: 2 | H33: 1 | I33: 34 | T33: 40.8
A34: H. Keenan | B34: {=_xlfn.XLOOKUP(A34,'Player List'!$A$2:$A$177,'Player List'!$B$2:$C$177)} -> Ireland | C34: Back Three | D34: =_xlfn.XLOOKUP(B34,$B$2:$B$7,$C$2:$C$7) -> Win | E34: 80 | I34: 86 | T34: 40.2 | U34: 1
A35: B. Aki | B35: {=_xlfn.XLOOKUP(A35,'Player List'!$A$2:$A$177,'Player List'!$B$2:$C$177)} -> Ireland | C35: Centre | D35: =_xlfn.XLOOKUP(B35,$B$2:$B$7,$C$2:$C$7) -> Win | E35: 80 | F35: 4 | H35: 1 | I35: 112 | L35: 1 | M35: 1 | T35: 63.4
A36: S. McCloskey | B36: {=_xlfn.XLOOKUP(A35,'Player List'!$A$2:$A$177,'Player List'!$B$2:$C$177)} -> Ireland | C36: Centre | D36: =_xlfn.XLOOKUP(B36,$B$2:$B$7,$C$2:$C$7) -> Win | E36: 20 | F36: 2 | I36: 13 | L36: 1 | T36: 13.6
A37: G. Ringrose | B37: {=_xlfn.XLOOKUP(A36,'Player List'!$A$2:$A$177,'Player List'!$B$2:$C$177)} -> Ireland | C37: Centre | D37: =_xlfn.XLOOKUP(B37,$B$2:$B$7,$C$2:$C$7) -> Win | E37: 60 | F37: 7 | I37: 66 | T37: 26.2
A38: R. Byrne | B38: {=_xlfn.XLOOKUP(A37,'Player List'!$A$2:$A$177,'Player List'!$B$2:$C$177)} -> Ireland | C38: Centre | D38: =_xlfn.XLOOKUP(B38,$B$2:$B$7,$C$2:$C$7) -> Win | E38: 80 | F38: 10 | I38: 49 | T38: 27.8
A39: J. Sexton | B39: {=_xlfn.XLOOKUP(A38,'Player List'!$A$2:$A$177,'Player List'!$B$2:$C$177)} -> Ireland | C39: Fly Half | D39: =_xlfn.XLOOKUP(B39,$B$2:$B$7,$C$2:$C$7) -> Win | E39: 12 | I39: 11 | O39: 1 | T39: 5.4
A40: C. Casey | B40: {=_xlfn.XLOOKUP(A39,'Player List'!$A$2:$A$177,'Player List'!$B$2:$C$177)} -> Ireland | C40: Fly Half | D40: =_xlfn.XLOOKUP(B40,$B$2:$B$7,$C$2:$C$7) -> Win | E40: 68 | F40: 7 | I40: 30 | L40: 1 | O40: 3 | P40: 2 | T40: 42.8
A41: C. Murray | B41: {=_xlfn.XLOOKUP(A40,'Player List'!$A$2:$A$177,'Player List'!$B$2:$C$177)} -> Ireland | C41: Scrum Half | D41: =_xlfn.XLOOKUP(B41,$B$2:$B$7,$C$2:$C$7) -> Win | E41: 16 | F41: 1 | I41: 1 | N41: 1 | T41: 9.8
A42: J. Conan | B42: {=_xlfn.XLOOKUP(A41,'Player List'!$A$2:$A$177,'Player List'!$B$2:$C$177)} -> Ireland | C42: Scrum Half | D42: =_xlfn.XLOOKUP(B42,$B$2:$B$7,$C$2:$C$7) -> Win | E42: 64 | F42: 1 | G42: 1 | H42: 1 | I42: 12 | N42: 1 | T42: 30.8
...

Sheet Round 2 Data
B2: Scotland | C2: Win | E2: Ireland | F2: 32 | G2: 19 | H2: France
B3: Wales | C3: Loss | E3: Scotland | F3: 35 | G3: 7 | H3: Wales
B4: Ireland | C4: Win | E4: England | F4: 31 | G4: 14 | H4: Italy
B5: England | C5: Win
B6: France | C6: Loss
B7: Italy | C7: Loss
A9: Name | B9: Nation | C9: Position | D9: Win/Loss | E9: Time Played | F9: Tackles | G9: Dominant Tackles | H9: Line Breaks | I9: Metres Carried | J9: 50-22 | K9: Lineout Steal | L9: Breakdown Steal | M9: Try | N9: Assists | O9: Conversion | P9: Penalty | Q9: Drop Goal | R9: Yellow Card | S9: Red Card | T9: Game Total | U9: MoM | V9: Total Points
A10: M. Hansen | B10: {=_xlfn.XLOOKUP(A10,'Player List'!$A$2:$A$177,'Player List'!$B$2:$C$177)} -> Ireland | C10: Back Three | D10: =_xlfn.XLOOKUP(B10,$B$2:$B$7,$C$2:$C$7) -> Win | E10: 80 | F10: 5 | I10: 63 | T10: 25.6
A11: H. Keenan | B11: {=_xlfn.XLOOKUP(A11,'Player List'!$A$2:$A$177,'Player List'!$B$2:$C$177)} -> Ireland | C11: Back Three | D11: =_xlfn.XLOOKUP(B11,$B$2:$B$7,$C$2:$C$7) -> Win | E11: 80 | F11: 3 | G11: 1 | H11: 2 | I11: 205 | J11: 1 | M11: 1 | T11: 98
A12: J. Lowe | B12: {=_xlfn.XLOOKUP(A12,'Player List'!$A$2:$A$177,'Player List'!$B$2:$C$177)} -> Ireland | C12: Back Three | D12: =_xlfn.XLOOKUP(B12,$B$2:$B$7,$C$2:$C$7) -> Win | E12: 80 | F12: 4 | H12: 1 | I12: 94 | M12: 1 | T12: 52.8
A13: B. Aki | B13: {=_xlfn.XLOOKUP(A13,'Player List'!$A$2:$A$177,'Player List'!$B$2:$C$177)} -> Ireland | C13: Centre | D13: =_xlfn.XLOOKUP(B13,$B$2:$B$7,$C$2:$C$7) -> Win | E13: 14 | F13: 3 | I13: 25 | T13: 9.4
A14: S. McCloskey | B14: {=_xlfn.XLOOKUP(A14,'Player List'!$A$2:$A$177,'Player List'!$B$2:$C$177)} -> Ireland | C14: Centre | D14: =_xlfn.XLOOKUP(B14,$B$2:$B$7,$C$2:$C$7) -> Win | E14: 66 | F14: 3 | I14: 69 | L14: 1 | T14: 30.4
A15: G. Ringrose | B15: {=_xlfn.XLOOKUP(A15,'Player List'!$A$2:$A$177,'Player List'!$B$2:$C$177)} -> Ireland | C15: Centre | D15: =_xlfn.XLOOKUP(B15,$B$2:$B$7,$C$2:$C$7) -> Win | E15: 80 | F15: 9 | G15: 1 | H15: 1 | I15: 64 | M15: 1 | N15: 1 | T15: 65.8
A16: R. Byrne | B16: {=_xlfn.XLOOKUP(A16,'Player List'!$A$2:$A$177,'Player List'!$B$2:$C$177)} -> Ireland | C16: Fly Half | D16: =_xlfn.XLOOKUP(B16,$B$2:$B$7,$C$2:$C$7) -> Win | E16: 32 | F16: 3 | I16: 10 | O16: 1 | P16: 1 | T16: 15.2
A17: J. Sexton | B17: {=_xlfn.XLOOKUP(A17,'Player List'!$A$2:$A$177,'Player List'!$B$2:$C$177)} -> Ireland | C17: Fly Half | D17: =_xlfn.XLOOKUP(B17,$B$2:$B$7,$C$2:$C$7) -> Win | E17: 48 | F17: 3 | H17: 2 | I17: 80 | O17: 2 | P17: 1 | T17: 46.8
A18: C. Casey | B18: {=_xlfn.XLOOKUP(A18,'Player List'!$A$2:$A$177,'Player List'!$B$2:$C$177)} -> Ireland | C18: Scrum Half | D18: =_xlfn.XLOOKUP(B18,$B$2:$B$7,$C$2:$C$7) -> Win | E18: 24 | F18: 1 | I18: 14 | T18: 6.2
A19: C. Murray | B19: {=_xlfn.XLOOKUP(A19,'Player List'!$A$2:$A$177,'Player List'!$B$2:$C$177)} -> Ireland | C19: Scrum Half | D19: =_xlfn.XLOOKUP(B19,$B$2:$B$7,$C$2:$C$7) -> Win | E19: 56 | F19: 3 | I19: 11 | T19: 10.8
A20: J. Conan | B20: {=_xlfn.XLOOKUP(A20,'Player List'!$A$2:$A$177,'Player List'!$B$2:$C$177)} -> Ireland | C20: Back Row | D20: =_xlfn.XLOOKUP(B20,$B$2:$B$7,$C$2:$C$7) -> Win | E20: 24 | F20: 2 | I20: 22 | T20: 8.8
A21: C. Doris | B21: {=_xlfn.XLOOKUP(A21,'Player List'!$A$2:$A$177,'Player List'!$B$2:$C$177)} -> Ireland | C21: Back Row | D21: =_xlfn.XLOOKUP(B21,$B$2:$B$7,$C$2:$C$7) -> Win | E21: 80 | F21: 6 | I21: 117 | L21: 1 | N21: 1 | T21: 66.4 | U21: 1
A22: P. O'Mahony | B22: {=_xlfn.XLOOKUP(A22,'Player List'!$A$2:$A$177,'Player List'!$B$2:$C$177)} -> Ireland | C22: Back Row | D22: =_xlfn.XLOOKUP(B22,$B$2:$B$7,$C$2:$C$7) -> Win | E22: 56 | F22: 7 | I22: 15 | T22: 15.6
A23: J. van der Flier | B23: {=_xlfn.XLOOKUP(A23,'Player List'!$A$2:$A$177,'Player List'!$B$2:$C$177)} -> Ireland | C23: Back Row | D23: =_xlfn.XLOOKUP(B23,$B$2:$B$7,$C$2:$C$7) -> Win | E23: 80 | F23: 12 | G23: 1 | I23: 51 | T23: 37.2
A24: T. Beirne | B24: {=_xlfn.XLOOKUP(A24,'Player List'!$A$2:$A$177,'Player List'!$B$2:$C$177)} -> Ireland | C24: Second Row | D24: =_xlfn.XLOOKUP(B24,$B$2:$B$7,$C$2:$C$7) -> Win | E24: 45 | F24: 10 | G24: 2 | H24: 1 | I24: 33 | L24: 1 | T24: 49.1
A25: I. Henderson | B25: {=_xlfn.XLOOKUP(A25,'Player List'!$A$2:$A$177,'Player List'!$B$2:$C$177)} -> Ireland | C25: Second Row | D25: =_xlfn.XLOOKUP(B25,$B$2:$B$7,$C$2:$C$7) -> Win | E25: 35 | F25: 4 | I25: 20 | T25: 11.5
A26: J. Ryan | B26: {=_xlfn.XLOOKUP(A26,'Player List'!$A$2:$A$177,'Player List'!$B$2:$C$177)} -> Ireland | C26: Second Row | D26: =_xlfn.XLOOKUP(B26,$B$2:$B$7,$C$2:$C$7) -> Win | E26: 80 | F26: 15 | G26: 1 | I26: 52 | T26: 40.4
A27: F. Bealham | B27: {=_xlfn.XLOOKUP(A27,'Player List'!$A$2:$A$177,'Player List'!$B$2:$C$177)} -> Ireland | C27: Prop | D27: =_xlfn.XLOOKUP(B27,$B$2:$B$7,$C$2:$C$7) -> Win | E27: 61 | F27: 12 | G27: 1 | I27: 11 | N27: 1 | T27: 34.3
A28: D. Kilcoyne | B28: {=_xlfn.XLOOKUP(A28,'Player List'!$A$2:$A$177,'Player List'!$B$2:$C$177)} -> Ireland | C28: Prop | D28: =_xlfn.XLOOKUP(B28,$B$2:$B$7,$C$2:$C$7) -> Win | E28: 11 | F28: 3 | I28: 9 | T28: 5.9
A29: T. O'Toole | B29: {=_xlfn.XLOOKUP(A29,'Player List'!$A$2:$A$177,'Player List'!$B$2:$C$177)} -> Ireland | C29: Prop | D29: =_xlfn.XLOOKUP(B29,$B$2:$B$7,$C$2:$C$7) -> Win | E29: 19 | I29: 52 | T29: 12.3
A30: A. Porter | B30: {=_xlfn.XLOOKUP(A30,'Player List'!$A$2:$A$177,'Player List'!$B$2:$C$177)} -> Ireland | C30: Prop | D30: =_xlfn.XLOOKUP(B30,$B$2:$B$7,$C$2:$C$7) -> Win | E30: 69 | F30: 6 | I30: 17 | M30: 1 | T30: 31.3
A31: R. Herring | B31: {=_xlfn.XLOOKUP(A31,'Player List'!$A$2:$A$177,'Player List'!$B$2:$C$177)} -> Ireland | C31: Hooker | D31: =_xlfn.XLOOKUP(B31,$B$2:$B$7,$C$2:$C$7) -> Win | E31: 25 | F31: 6 | I31: 7 | T31: 9.9
A32: R. Kelleher | B32: {=_xlfn.XLOOKUP(A32,'Player List'!$A$2:$A$177,'Player List'!$B$2:$C$177)} -> Ireland | C32: Hooker | D32: =_xlfn.XLOOKUP(B32,$B$2:$B$7,$C$2:$C$7) -> Win | E32: 55 | F32: 9 | G32: 2 | I32: 38 | T32: 36.1
A33: D. Penaud | B33: {=_xlfn.XLOOKUP(A33,'Player List'!$A$2:$A$177,'Player List'!$B$2:$C$177)} -> France | C33: Back Three | D33: =_xlfn.XLOOKUP(B33,$B$2:$B$7,$C$2:$C$7) -> Loss | E33: 80 | F33: 4 | H33: 1 | I33: 134 | M33: 1 | T33: 52.8
A34: T. Ramos | B34: {=_xlfn.XLOOKUP(A34,'Player List'!$A$2:$A$177,'Player List'!$B$2:$C$177)} -> France | C34: Back Three | D34: =_xlfn.XLOOKUP(B34,$B$2:$B$7,$C$2:$C$7) -> Loss | E34: 61 | F34: 3 | I34: 90 | O34: 1 | P34: 3 | Q34: 1 | T34: 45
A35: E. Dumortier | B35: {=_xlfn.XLOOKUP(A35,'Player List'!$A$2:$A$177,'Player List'!$B$2:$C$177)} -> France | C35: Centre | D35: =_xlfn.XLOOKUP(B35,$B$2:$B$7,$C$2:$C$7) -> Loss | E35: 68 | F35: 2 | H35: 2 | I35: 88 | T35: 33.6
A36: G. Fickou | B36: {=_xlfn.XLOOKUP(A36,'Player List'!$A$2:$A$177,'Player List'!$B$2:$C$177)} -> France | C36: Centre | D36: =_xlfn.XLOOKUP(B36,$B$2:$B$7,$C$2:$C$7) -> Loss | E36: 80 | F36: 14 | I36: 83 | T36: 30.6
A37: Y. Moefana | B37: {=_xlfn.XLOOKUP(A37,'Player List'!$A$2:$A$177,'Player List'!$B$2:$C$177)} -> France | C37: Centre | D37: =_xlfn.XLOOKUP(B37,$B$2:$B$7,$C$2:$C$7) -> Loss | E37: 80 | F37: 9 | I37: 57 | T37: 20.4
A38: M. Jalibert | B38: {=_xlfn.XLOOKUP(A38,'Player List'!$A$2:$A$177,'Player List'!$B$2:$C$177)} -> France | C38: Fly Half | D38: =_xlfn.XLOOKUP(B38,$B$2:$B$7,$C$2:$C$7) -> Loss | E38: 19 | F38: 2 | I38: 19 | T38: 5.8
A39: R. Ntamack | B39: {=_xlfn.XLOOKUP(A39,'Player List'!$A$2:$A$177,'Player List'!$B$2:$C$177)} -> France | C39: Fly Half | D39: =_xlfn.XLOOKUP(B39,$B$2:$B$7,$C$2:$C$7) -> Loss | E39: 80 | F39: 12 | I39: 51 | T39: 22.2
A40: A. Dupont | B40: {=_xlfn.XLOOKUP(A40,'Player List'!$A$2:$A$177,'Player List'!$B$2:$C$177)} -> France | C40: Scrum Half | D40: =_xlfn.XLOOKUP(B40,$B$2:$B$7,$C$2:$C$7) -> Loss | E40: 80 | F40: 10 | G40: 1 | H40: 2 | I40: 90 | T40: 49
A41: G. Alldritt | B41: {=_xlfn.XLOOKUP(A41,'Player List'!$A$2:$A$177,'Player List'!$B$2:$C$177)} -> France | C41: Back Row | D41: =_xlfn.XLOOKUP(B41,$B$2:$B$7,$C$2:$C$7) -> Loss | E41: 52 | F41: 13 | I41: 17 | T41: 16.4
A42: F. Cros | B42: {=_xlfn.XLOOKUP(A42,'Player List'!$A$2:$A$177,'Player List'!$B$2:$C$177)} -> France | C42: Back Row | D42: =_xlfn.XLOOKUP(B42,$B$2:$B$7,$C$2:$C$7) -> Loss | E42: 11 | F42: 6 | T42: 6
...

Sheet Round 3 Data
B2: Scotland | C2: Loss | E2: Italy | F2: 20 | G2: 34 | H2: Ireland
B3: Wales | C3: Loss | E3: Wales | F3: 10 | G3: 20 | H3: England
B4: Ireland | C4: Win | E4: France | F4: 32 | G4: 21 | H4: Scotland
B5: England | C5: Win
B6: France | C6: Win
B7: Italy | C7: Loss
A9: Name | B9: Nation | C9: Position | D9: Win/Loss | E9: Time Played | F9: Tackles | G9: Dominant Tackles | H9: Line Breaks | I9: Metres Carried | J9: 50-22 | K9: Lineout Steal | L9: Breakdown Steal | M9: Try | N9: Assists | O9: Conversion | P9: Penalty | Q9: Drop Goal | R9: Yellow Card | S9: Red Card | T9: Game Total | U9: MoM | V9: Total Points
A10: M. Hansen | B10: {=_xlfn.XLOOKUP(A10,'Player List'!$A$2:$A$177,'Player List'!$B$2:$C$177)} -> Ireland | C10: Back Three | D10: =_xlfn.XLOOKUP(B10,$B$2:$B$7,$C$2:$C$7) -> Win | E10: 80 | F10: 2 | H10: 3 | I10: 75 | L10: 1 | M10: 2 | T10: 98 | U10: 1
A11: H. Keenan | B11: {=_xlfn.XLOOKUP(A11,'Player List'!$A$2:$A$177,'Player List'!$B$2:$C$177)} -> Ireland | C11: Back Three | D11: =_xlfn.XLOOKUP(B11,$B$2:$B$7,$C$2:$C$7) -> Win | E11: 80 | F11: 3 | G11: 1 | I11: 124 | M11: 1 | T11: 57.8
A12: J. Lowe | B12: {=_xlfn.XLOOKUP(A12,'Player List'!$A$2:$A$177,'Player List'!$B$2:$C$177)} -> Ireland | C12: Back Three | D12: =_xlfn.XLOOKUP(B12,$B$2:$B$7,$C$2:$C$7) -> Win | E12: 80 | F12: 1 | G12: 2 | H12: 4 | I12: 131 | N12: 2 | T12: 91.2
A13: J. O'Brien | B13: {=_xlfn.XLOOKUP(A13,'Player List'!$A$2:$A$177,'Player List'!$B$2:$C$177)} -> Ireland | C13: Back Three | D13: =_xlfn.XLOOKUP(B13,$B$2:$B$7,$C$2:$C$7) -> Win | E13: 8 | T13: 0.8
A14: B. Aki | B14: {=_xlfn.XLOOKUP(A14,'Player List'!$A$2:$A$177,'Player List'!$B$2:$C$177)} -> Ireland | C14: Centre | D14: =_xlfn.XLOOKUP(B14,$B$2:$B$7,$C$2:$C$7) -> Win | E14: 80 | F14: 7 | H14: 1 | I14: 107 | L14: 1 | M14: 1 | N14: 1 | T14: 72.4
A15: S. McCloskey | B15: {=_xlfn.XLOOKUP(A15,'Player List'!$A$2:$A$177,'Player List'!$B$2:$C$177)} -> Ireland | C15: Centre | D15: =_xlfn.XLOOKUP(B15,$B$2:$B$7,$C$2:$C$7) -> Win | E15: 72 | F15: 14 | I15: 69 | N15: 1 | T15: 42
A16: R. Byrne | B16: {=_xlfn.XLOOKUP(A16,'Player List'!$A$2:$A$177,'Player List'!$B$2:$C$177)} -> Ireland | C16: Fly Half | D16: =_xlfn.XLOOKUP(B16,$B$2:$B$7,$C$2:$C$7) -> Win | E16: 78 | F16: 4 | I16: 12 | O16: 3 | P16: 1 | T16: 25.2
A17: J. Crowley | B17: {=_xlfn.XLOOKUP(A17,'Player List'!$A$2:$A$177,'Player List'!$B$2:$C$177)} -> Ireland | C17: Fly Half | D17: =_xlfn.XLOOKUP(B17,$B$2:$B$7,$C$2:$C$7) -> Win | E17: 2 | F17: 2 | T17: 2.2
A18: C. Casey | B18: {=_xlfn.XLOOKUP(A18,'Player List'!$A$2:$A$177,'Player List'!$B$2:$C$177)} -> Ireland | C18: Scrum Half | D18: =_xlfn.XLOOKUP(B18,$B$2:$B$7,$C$2:$C$7) -> Win | E18: 65 | F18: 2 | I18: 4 | T18: 9.3
A19: C. Murray | B19: {=_xlfn.XLOOKUP(A19,'Player List'!$A$2:$A$177,'Player List'!$B$2:$C$177)} -> Ireland | C19: Scrum Half | D19: =_xlfn.XLOOKUP(B19,$B$2:$B$7,$C$2:$C$7) -> Win | E19: 15 | F19: 1 | I19: 6 | N19: 1 | T19: 10.7
A20: J. Conan | B20: {=_xlfn.XLOOKUP(A20,'Player List'!$A$2:$A$177,'Player List'!$B$2:$C$177)} -> Ireland | C20: Back Row | D20: =_xlfn.XLOOKUP(B20,$B$2:$B$7,$C$2:$C$7) -> Win | E20: 56 | F20: 4 | I20: 42 | T20: 18
A21: C. Doris | B21: {=_xlfn.XLOOKUP(A21,'Player List'!$A$2:$A$177,'Player List'!$B$2:$C$177)} -> Ireland | C21: Back Row | D21: =_xlfn.XLOOKUP(B21,$B$2:$B$7,$C$2:$C$7) -> Win | E21: 80 | F21: 10 | G21: 1 | I21: 43 | L21: 1 | T21: 40.6
A22: P. O'Mahony | B22: {=_xlfn.XLOOKUP(A22,'Player List'!$A$2:$A$177,'Player List'!$B$2:$C$177)} -> Ireland | C22: Back Row | D22: =_xlfn.XLOOKUP(B22,$B$2:$B$7,$C$2:$C$7) -> Win | E22: 24 | F22: 4 | G22: 1 | I22: 4 | T22: 14.2
A23: J. van der Flier | B23: {=_xlfn.XLOOKUP(A23,'Player List'!$A$2:$A$177,'Player List'!$B$2:$C$177)} -> Ireland | C23: Back Row | D23: =_xlfn.XLOOKUP(B23,$B$2:$B$7,$C$2:$C$7) -> Win | E23: 80 | F23: 12 | H23: 1 | I23: 52 | T23: 37.4
A24: R. Baird | B24: {=_xlfn.XLOOKUP(A24,'Player List'!$A$2:$A$177,'Player List'!$B$2:$C$177)} -> Ireland | C24: Second Row | D24: =_xlfn.XLOOKUP(B24,$B$2:$B$7,$C$2:$C$7) -> Win | E24: 28 | F24: 1 | G24: 1 | I24: 8 | K24: 1 | L24: 1 | T24: 26.4
A25: I. Henderson | B25: {=_xlfn.XLOOKUP(A25,'Player List'!$A$2:$A$177,'Player List'!$B$2:$C$177)} -> Ireland | C25: Second Row | D25: =_xlfn.XLOOKUP(B25,$B$2:$B$7,$C$2:$C$7) -> Win | E25: 52 | F25: 7 | I25: 13 | T25: 14.8
A26: J. Ryan | B26: {=_xlfn.XLOOKUP(A26,'Player List'!$A$2:$A$177,'Player List'!$B$2:$C$177)} -> Ireland | C26: Second Row | D26: =_xlfn.XLOOKUP(B26,$B$2:$B$7,$C$2:$C$7) -> Win | E26: 80 | F26: 9 | G26: 1 | I26: 53 | M26: 1 | T26: 49.6
A27: F. Bealham | B27: {=_xlfn.XLOOKUP(A27,'Player List'!$A$2:$A$177,'Player List'!$B$2:$C$177)} -> Ireland | C27: Prop | D27: =_xlfn.XLOOKUP(B27,$B$2:$B$7,$C$2:$C$7) -> Win | E27: 37 | F27: 2 | G27: 1 | I27: 1 | T27: 12.9
A28: D. Kilcoyne | B28: {=_xlfn.XLOOKUP(A28,'Player List'!$A$2:$A$177,'Player List'!$B$2:$C$177)} -> Ireland | C28: Prop | D28: =_xlfn.XLOOKUP(B28,$B$2:$B$7,$C$2:$C$7) -> Win | E28: 15 | G28: 1 | I28: 7 | T28: 9.9
A29: T. O'Toole | B29: {=_xlfn.XLOOKUP(A29,'Player List'!$A$2:$A$177,'Player List'!$B$2:$C$177)} -> Ireland | C29: Prop | D29: =_xlfn.XLOOKUP(B29,$B$2:$B$7,$C$2:$C$7) -> Win | E29: 43 | F29: 6 | I29: 24 | L29: 1 | T29: 22.1
A30: A. Porter | B30: {=_xlfn.XLOOKUP(A30,'Player List'!$A$2:$A$177,'Player List'!$B$2:$C$177)} -> Ireland | C30: Prop | D30: =_xlfn.XLOOKUP(B30,$B$2:$B$7,$C$2:$C$7) -> Win | E30: 65 | F30: 3 | I30: 10 | L30: 1 | T30: 18.5
A31: R. Kelleher | B31: {=_xlfn.XLOOKUP(A31,'Player List'!$A$2:$A$177,'Player List'!$B$2:$C$177)} -> Ireland | C31: Hooker | D31: =_xlfn.XLOOKUP(B31,$B$2:$B$7,$C$2:$C$7) -> Win | E31: 56 | F31: 9 | I31: 23 | L31: 1 | T31: 26.2
A32: D. Sheehan | B32: {=_xlfn.XLOOKUP(A32,'Player List'!$A$2:$A$177,'Player List'!$B$2:$C$177)} -> Ireland | C32: Hooker | D32: =_xlfn.XLOOKUP(B32,$B$2:$B$7,$C$2:$C$7) -> Win | E32: 24 | F32: 2 | G32: 2 | I32: 5 | T32: 19.4
A33: P. Bruno | B33: {=_xlfn.XLOOKUP(A33,'Player List'!$A$2:$A$177,'Player List'!$B$2:$C$177)} -> Italy | C33: Back Three | D33: =_xlfn.XLOOKUP(B33,$B$2:$B$7,$C$2:$C$7) -> Loss | E33: 80 | F33: 3 | H33: 1 | I33: 176 | M33: 1 | T33: 60.2
A34: A. Capuozzo | B34: {=_xlfn.XLOOKUP(A34,'Player List'!$A$2:$A$177,'Player List'!$B$2:$C$177)} -> Italy | C34: Back Three | D34: =_xlfn.XLOOKUP(B34,$B$2:$B$7,$C$2:$C$7) -> Loss | E34: 80 | F34: 3 | G34: 1 | H34: 1 | I34: 60 | L34: 1 | T34: 36
A35: A. Fusco | B35: {=_xlfn.XLOOKUP(A35,'Player List'!$A$2:$A$177,'Player List'!$B$2:$C$177)} -> Italy | C35: Back Three | D35: =_xlfn.XLOOKUP(B35,$B$2:$B$7,$C$2:$C$7) -> Loss | E35: 13 | T35: 0
A36: T. Menoncello | B36: {=_xlfn.XLOOKUP(A36,'Player List'!$A$2:$A$177,'Player List'!$B$2:$C$177)} -> Italy | C36: Back Three | D36: =_xlfn.XLOOKUP(B36,$B$2:$B$7,$C$2:$C$7) -> Loss | E36: 78 | F36: 12 | H36: 1 | I36: 72 | T36: 33.4
A37: E. Padovani | B37: {=_xlfn.XLOOKUP(A37,'Player List'!$A$2:$A$177,'Player List'!$B$2:$C$177)} -> Italy | C37: Back Three | D37: =_xlfn.XLOOKUP(B37,$B$2:$B$7,$C$2:$C$7) -> Loss | E37: 80 | I37: 51 | T37: 10.2
A38: J. Brex | B38: {=_xlfn.XLOOKUP(A38,'Player List'!$A$2:$A$177,'Player List'!$B$2:$C$177)} -> Italy | C38: Centre | D38: =_xlfn.XLOOKUP(B38,$B$2:$B$7,$C$2:$C$7) -> Loss | E38: 80 | F38: 8 | G38: 1 | I38: 26 | T38: 20.2
A39: L. Morisi | B39: {=_xlfn.XLOOKUP(A39,'Player List'!$A$2:$A$177,'Player List'!$B$2:$C$177)} -> Italy | C39: Centre | D39: =_xlfn.XLOOKUP(B39,$B$2:$B$7,$C$2:$C$7) -> Loss | E39: 2 | F39: 1 | T39: 1
A40: T. Allan | B40: {=_xlfn.XLOOKUP(A40,'Player List'!$A$2:$A$177,'Player List'!$B$2:$C$177)} -> Italy | C40: Fly Half | D40: =_xlfn.XLOOKUP(B40,$B$2:$B$7,$C$2:$C$7) -> Loss | E40: 8 | F40: 1 | I40: 14 | T40: 3.8
A41: P. Garbisi | B41: {=_xlfn.XLOOKUP(A41,'Player List'!$A$2:$A$177,'Player List'!$B$2:$C$177)} -> Italy | C41: Fly Half | D41: =_xlfn.XLOOKUP(B41,$B$2:$B$7,$C$2:$C$7) -> Loss | E41: 72 | F41: 5 | I41: 42 | O41: 2 | P41: 2 | T41: 27.4
A42: S. Varney | B42: {=_xlfn.XLOOKUP(A42,'Player List'!$A$2:$A$177,'Player List'!$B$2:$C$177)} -> Italy | C42: Scrum Half | D42: =_xlfn.XLOOKUP(B42,$B$2:$B$7,$C$2:$C$7) -> Loss | E42: 67 | F42: 1 | G42: 1 | I42: 12 | M42: 1 | T42: 25.4
...

Sheet Round 4 Data
B2: Scotland | C2: Loss | E2: Italy | F2: 17 | G2: 29 | H2: Wales
B3: Wales | C3: Win | E3: England | F3: 53 | G3: 10 | H3: France
B4: Ireland | C4: Win | E4: Scotland | F4: 7 | G4: 22 | H4: Ireland
B5: England | C5: Loss
B6: France | C6: Win
B7: Italy | C7: Loss
A9: Name | B9: Nation | C9: Position | D9: Win/Loss | E9: Time Played | F9: Tackles | G9: Dominant Tackles | H9: Line Breaks | I9: Metres Carried | J9: 50-22 | K9: Lineout Steal | L9: Breakdown Steal | M9: Try | N9: Assists | O9: Conversion | P9: Penalty | Q9: Drop Goal | R9: Yellow Card | S9: Red Card | T9: Game Total | U9: MoM | V9: Total Points
A10: P. Bruno | B10: {=_xlfn.XLOOKUP(A10,'Player List'!$A$2:$A$177,'Player List'!$B$2:$C$177)} -> Italy | C10: Back Three | D10: =_xlfn.XLOOKUP(B10,$B$2:$B$7,$C$2:$C$7) -> Loss | E10: 69 | F10: 2 | I10: 29 | N10: 1 | R10: 1 | T10: 9.8
A11: A. Fusco | B11: {=_xlfn.XLOOKUP(A11,'Player List'!$A$2:$A$177,'Player List'!$B$2:$C$177)} -> Italy | C11: Back Three | D11: =_xlfn.XLOOKUP(B11,$B$2:$B$7,$C$2:$C$7) -> Loss | E11: 24 | H11: 1 | I11: 50 | T11: 17
A12: T. Menoncello | B12: {=_xlfn.XLOOKUP(A12,'Player List'!$A$2:$A$177,'Player List'!$B$2:$C$177)} -> Italy | C12: Back Three | D12: =_xlfn.XLOOKUP(B12,$B$2:$B$7,$C$2:$C$7) -> Loss | E12: 59 | F12: 7 | G12: 1 | H12: 1 | I12: 79 | T12: 36.8
A13: E. Padovani | B13: {=_xlfn.XLOOKUP(A13,'Player List'!$A$2:$A$177,'Player List'!$B$2:$C$177)} -> Italy | C13: Back Three | D13: =_xlfn.XLOOKUP(B13,$B$2:$B$7,$C$2:$C$7) -> Loss | E13: 80 | F13: 1 | G13: 1 | H13: 1 | I13: 51 | T13: 25.2
A14: J. Brex | B14: {=_xlfn.XLOOKUP(A14,'Player List'!$A$2:$A$177,'Player List'!$B$2:$C$177)} -> Italy | C14: Centre | D14: =_xlfn.XLOOKUP(B14,$B$2:$B$7,$C$2:$C$7) -> Loss | E14: 80 | F14: 2 | H14: 1 | I14: 90 | M14: 1 | T14: 42
A15: L. Morisi | B15: {=_xlfn.XLOOKUP(A15,'Player List'!$A$2:$A$177,'Player List'!$B$2:$C$177)} -> Italy | C15: Centre | D15: =_xlfn.XLOOKUP(B15,$B$2:$B$7,$C$2:$C$7) -> Loss | E15: 21 | I15: 24 | T15: 4.8
A16: T. Allan | B16: {=_xlfn.XLOOKUP(A16,'Player List'!$A$2:$A$177,'Player List'!$B$2:$C$177)} -> Italy | C16: Fly Half | D16: =_xlfn.XLOOKUP(B16,$B$2:$B$7,$C$2:$C$7) -> Loss | E16: 80 | H16: 3 | I16: 78 | N16: 1 | O16: 2 | P16: 1 | T16: 52.6
A17: P. Garbisi | B17: {=_xlfn.XLOOKUP(A17,'Player List'!$A$2:$A$177,'Player List'!$B$2:$C$177)} -> Italy | C17: Fly Half | D17: =_xlfn.XLOOKUP(B17,$B$2:$B$7,$C$2:$C$7) -> Loss | E17: 80 | F17: 6 | H17: 1 | I17: 37 | T17: 20.4
A18: S. Varney | B18: {=_xlfn.XLOOKUP(A18,'Player List'!$A$2:$A$177,'Player List'!$B$2:$C$177)} -> Italy | C18: Scrum Half | D18: =_xlfn.XLOOKUP(B18,$B$2:$B$7,$C$2:$C$7) -> Loss | E18: 56 | F18: 3 | I18: 38 | T18: 10.6
A19: E. Iachizzi | B19: {=_xlfn.XLOOKUP(A19,'Player List'!$A$2:$A$177,'Player List'!$B$2:$C$177)} -> Italy | C19: Back Row | D19: =_xlfn.XLOOKUP(B19,$B$2:$B$7,$C$2:$C$7) -> Loss | E19: 20 | F19: 1 | H19: 1 | I19: 28 | L19: 1 | T19: 20.6
A20: M. Lamaro | B20: {=_xlfn.XLOOKUP(A20,'Player List'!$A$2:$A$177,'Player List'!$B$2:$C$177)} -> Italy | C20: Back Row | D20: =_xlfn.XLOOKUP(B20,$B$2:$B$7,$C$2:$C$7) -> Loss | E20: 77 | F20: 7 | I20: 24 | T20: 11.8
A21: S. Negri | B21: {=_xlfn.XLOOKUP(A21,'Player List'!$A$2:$A$177,'Player List'!$B$2:$C$177)} -> Italy | C21: Back Row | D21: =_xlfn.XLOOKUP(B21,$B$2:$B$7,$C$2:$C$7) -> Loss | E21: 52 | F21: 5 | H21: 1 | I21: 50 | M21: 1 | T21: 37
A22: G. Pettinelli | B22: {=_xlfn.XLOOKUP(A22,'Player List'!$A$2:$A$177,'Player List'!$B$2:$C$177)} -> Italy | C22: Back Row | D22: =_xlfn.XLOOKUP(B22,$B$2:$B$7,$C$2:$C$7) -> Loss | E22: 3 | T22: 0
A23: N. Cannone | B23: {=_xlfn.XLOOKUP(A23,'Player List'!$A$2:$A$177,'Player List'!$B$2:$C$177)} -> Italy | C23: Second Row | D23: =_xlfn.XLOOKUP(B23,$B$2:$B$7,$C$2:$C$7) -> Loss | E23: 60 | F23: 3 | I23: 16 | T23: 6.2
A24: L. Cannone | B24: {=_xlfn.XLOOKUP(A24,'Player List'!$A$2:$A$177,'Player List'!$B$2:$C$177)} -> Italy | C24: Second Row | D24: =_xlfn.XLOOKUP(B24,$B$2:$B$7,$C$2:$C$7) -> Loss | E24: 71 | F24: 7 | G24: 1 | I24: 51 | R24: 1 | T24: 19.2
A25: F. Ruzza | B25: {=_xlfn.XLOOKUP(A25,'Player List'!$A$2:$A$177,'Player List'!$B$2:$C$177)} -> Italy | C25: Second Row | D25: =_xlfn.XLOOKUP(B25,$B$2:$B$7,$C$2:$C$7) -> Loss | E25: 80 | F25: 3 | I25: 35 | T25: 10
A26: M. Zuliani | B26: {=_xlfn.XLOOKUP(A26,'Player List'!$A$2:$A$177,'Player List'!$B$2:$C$177)} -> Italy | C26: Second Row | D26: =_xlfn.XLOOKUP(B26,$B$2:$B$7,$C$2:$C$7) -> Loss | E26: 28 | F26: 1 | H26: 1 | I26: 36 | L26: 1 | T26: 22.2
A27: S. Ferrari | B27: {=_xlfn.XLOOKUP(A27,'Player List'!$A$2:$A$177,'Player List'!$B$2:$C$177)} -> Italy | C27: Prop | D27: =_xlfn.XLOOKUP(B27,$B$2:$B$7,$C$2:$C$7) -> Loss | E27: 42 | F27: 4 | G27: 1 | T27: 11
A28: D. Fischetti | B28: {=_xlfn.XLOOKUP(A28,'Player List'!$A$2:$A$177,'Player List'!$B$2:$C$177)} -> Italy | C28: Prop | D28: =_xlfn.XLOOKUP(B28,$B$2:$B$7,$C$2:$C$7) -> Loss | E28: 62 | F28: 5 | I28: 39 | T28: 12.8
A29: M. Riccioni | B29: {=_xlfn.XLOOKUP(A29,'Player List'!$A$2:$A$177,'Player List'!$B$2:$C$177)} -> Italy | C29: Prop | D29: =_xlfn.XLOOKUP(B29,$B$2:$B$7,$C$2:$C$7) -> Loss | E29: 38 | F29: 2 | I29: 14 | T29: 4.8
A30: F. Zani | B30: {=_xlfn.XLOOKUP(A30,'Player List'!$A$2:$A$177,'Player List'!$B$2:$C$177)} -> Italy | C30: Prop | D30: =_xlfn.XLOOKUP(B30,$B$2:$B$7,$C$2:$C$7) -> Loss | E30: 18 | T30: 0
A31: L. Bigi | B31: {=_xlfn.XLOOKUP(A31,'Player List'!$A$2:$A$177,'Player List'!$B$2:$C$177)} -> Italy | C31: Hooker | D31: =_xlfn.XLOOKUP(B31,$B$2:$B$7,$C$2:$C$7) -> Loss | E31: 28 | F31: 3 | T31: 3
A32: G. Nicotera | B32: {=_xlfn.XLOOKUP(A32,'Player List'!$A$2:$A$177,'Player List'!$B$2:$C$177)} -> Italy | C32: Hooker | D32: =_xlfn.XLOOKUP(B32,$B$2:$B$7,$C$2:$C$7) -> Loss | E32: 52 | F32: 11 | I32: 17 | L32: 1 | T32: 21.4
A33: J. Adams | B33: {=_xlfn.XLOOKUP(A33,'Player List'!$A$2:$A$177,'Player List'!$B$2:$C$177)} -> Wales | C33: Back Three | D33: =_xlfn.XLOOKUP(B33,$B$2:$B$7,$C$2:$C$7) -> Win | E33: 51 | F33: 1 | G33: 1 | H33: 1 | I33: 31 | T33: 26.3
A34: R. Dyer | B34: {=_xlfn.XLOOKUP(A34,'Player List'!$A$2:$A$177,'Player List'!$B$2:$C$177)} -> Wales | C34: Back Three | D34: =_xlfn.XLOOKUP(B34,$B$2:$B$7,$C$2:$C$7) -> Win | E34: 80 | F34: 4 | G34: 1 | H34: 1 | I34: 19 | M34: 1 | T34: 44.8
A35: L. Rees-Zammit | B35: {=_xlfn.XLOOKUP(A35,'Player List'!$A$2:$A$177,'Player List'!$B$2:$C$177)} -> Wales | C35: Back Three | D35: =_xlfn.XLOOKUP(B35,$B$2:$B$7,$C$2:$C$7) -> Win | E35: 29 | F35: 3 | I35: 46 | T35: 15.1
A36: L. Williams | B36: {=_xlfn.XLOOKUP(A36,'Player List'!$A$2:$A$177,'Player List'!$B$2:$C$177)} -> Wales | C36: Back Three | D36: =_xlfn.XLOOKUP(B36,$B$2:$B$7,$C$2:$C$7) -> Win | E36: 62 | F36: 1 | H36: 1 | I36: 87 | L36: 1 | M36: 1 | T36: 53.6
A37: M. Grady | B37: {=_xlfn.XLOOKUP(A37,'Player List'!$A$2:$A$177,'Player List'!$B$2:$C$177)} -> Wales | C37: Centre | D37: =_xlfn.XLOOKUP(B37,$B$2:$B$7,$C$2:$C$7) -> Win | E37: 80 | F37: 5 | I37: 26 | T37: 18.2
A38: J. Hawkins | B38: {=_xlfn.XLOOKUP(A38,'Player List'!$A$2:$A$177,'Player List'!$B$2:$C$177)} -> Wales | C38: Centre | D38: =_xlfn.XLOOKUP(B38,$B$2:$B$7,$C$2:$C$7) -> Win | E38: 80 | F38: 3 | G38: 1 | I38: 97 | T38: 37.4
A39: G. North | B39: {=_xlfn.XLOOKUP(A39,'Player List'!$A$2:$A$177,'Player List'!$B$2:$C$177)} -> Wales | C39: Centre | D39: =_xlfn.XLOOKUP(B39,$B$2:$B$7,$C$2:$C$7) -> Win | E39: 18 | F39: 1 | T39: 2.8
A40: O. Williams | B40: {=_xlfn.XLOOKUP(A40,'Player List'!$A$2:$A$177,'Player List'!$B$2:$C$177)} -> Wales | C40: Fly Half | D40: =_xlfn.XLOOKUP(B40,$B$2:$B$7,$C$2:$C$7) -> Win | E40: 80 | F40: 8 | I40: 19 | O40: 2 | P40: 1 | T40: 28.8
A41: R. Webb | B41: {=_xlfn.XLOOKUP(A41,'Player List'!$A$2:$A$177,'Player List'!$B$2:$C$177)} -> Wales | C41: Scrum Half | D41: =_xlfn.XLOOKUP(B41,$B$2:$B$7,$C$2:$C$7) -> Win | E41: 54 | F41: 5 | G41: 1 | H41: 1 | I41: 28 | J41: 1 | N41: 2 | T41: 69 | U41: 1
A42: T. Williams | B42: {=_xlfn.XLOOKUP(A42,'Player List'!$A$2:$A$177,'Player List'!$B$2:$C$177)} -> Wales | C42: Scrum Half | D42: =_xlfn.XLOOKUP(B42,$B$2:$B$7,$C$2:$C$7) -> Win | E42: 26 | F42: 2 | T42: 4.6
...

Sheet Summary Data
E2: Average
A3: Name | B3: Nation | C3: Position | D3: Games Played | E3: Time Played | F3: Tackles | G3: Dominant Tackles | H3: Line Breaks | I3: Metres Carried | J3: 50-22 | K3: Lineout Steal | L3: Breakdown Steal | M3: Try | N3: Assists | O3: Conversion | P3: Penalty | Q3: Drop Goal | R3: Yellow Card | S3: Red Card | T3: Total MoM
A4: J. Adams | B4: Wales | C4: Back Three | D4: =IF(_xlfn.XLOOKUP('Summary Data'!A4,'Round 1 Data'!$A$10:$A$143,'Round 1 Data'!$E$10:$E$144,0)=0,0,1)+IF(_xlfn.XLOOKUP('Summary Data'!A4,'Round 2 Data'!$A$10:$A$146,'Round 2 Data'!$E$10:$E$146,0)=0,0,1)+IF(_xlfn.XLOOKUP('Summary Data'!A4,'Round 3 Data'!$A$10:$A$145,'Round 3 Data'!$E$10:$E$145,0)=0,0,1)+IF(_xlfn.XLOOKUP('Summary Data'!A4,'Round 4 Data'!$A$10:$A$147,'Round 4 Data'!$E$10:$E$147,0)=0,0,1) -> #VALUE! | E4: =(_xlfn.XLOOKUP('Summary Data'!$A4,'Round 1 Data'!$A$10:$A$143,'Round 1 Data'!E$10:E$144,0)+_xlfn.XLOOKUP('Summary Data'!$A4,'Round 2 Data'!$A$10:$A$146,'Round 2 Data'!E$10:E$146,0)+_xlfn.XLOOKUP('Summary Data'!$A4,'Round 3 Data'!$A$10:$A$145,'Round 3 Data'!E$10:E$145,0)+_xlfn.XLOOKUP('Summary Data'!$A4,'Round 4 Data'!$A$10:$A$147,'Round 4 Data'!E$10:E$147,0))/$D4 -> #VALUE! | F4: =(_xlfn.XLOOKUP('Summary Data'!$A4,'Round 1 Data'!$A$10:$A$143,'Round 1 Data'!F$10:F$144,0)+_xlfn.XLOOKUP('Summary Data'!$A4,'Round 2 Data'!$A$10:$A$146,'Round 2 Data'!F$10:F$146,0)+_xlfn.XLOOKUP('Summary Data'!$A4,'Round 3 Data'!$A$10:$A$145,'Round 3 Data'!F$10:F$145,0)+_xlfn.XLOOKUP('Summary Data'!$A4,'Round 4 Data'!$A$10:$A$147,'Round 4 Data'!F$10:F$147,0))/$D4 -> #VALUE! | G4: =(_xlfn.XLOOKUP('Summary Data'!$A4,'Round 1 Data'!$A$10:$A$143,'Round 1 Data'!G$10:G$144,0)+_xlfn.XLOOKUP('Summary Data'!$A4,'Round 2 Data'!$A$10:$A$146,'Round 2 Data'!G$10:G$146,0)+_xlfn.XLOOKUP('Summary Data'!$A4,'Round 3 Data'!$A$10:$A$145,'Round 3 Data'!G$10:G$145,0)+_xlfn.XLOOKUP('Summary Data'!$A4,'Round 4 Data'!$A$10:$A$147,'Round 4 Data'!G$10:G$147,0))/$D4 -> #VALUE! | H4: =(_xlfn.XLOOKUP('Summary Data'!$A4,'Round 1 Data'!$A$10:$A$143,'Round 1 Data'!H$10:H$144,0)+_xlfn.XLOOKUP('Summary Data'!$A4,'Round 2 Data'!$A$10:$A$146,'Round 2 Data'!H$10:H$146,0)+_xlfn.XLOOKUP('Summary Data'!$A4,'Round 3 Data'!$A$10:$A$145,'Round 3 Data'!H$10:H$145,0)+_xlfn.XLOOKUP('Summary Data'!$A4,'Round 4 Data'!$A$10:$A$147,'Round 4 Data'!H$10:H$147,0))/$D4 -> #VALUE! | I4: =(_xlfn.XLOOKUP('Summary Data'!$A4,'Round 1 Data'!$A$10:$A$143,'Round 1 Data'!I$10:I$144,0)+_xlfn.XLOOKUP('Summary Data'!$A4,'Round 2 Data'!$A$10:$A$146,'Round 2 Data'!I$10:I$146,0)+_xlfn.XLOOKUP('Summary Data'!$A4,'Round 3 Data'!$A$10:$A$145,'Round 3 Data'!I$10:I$145,0)+_xlfn.XLOOKUP('Summary Data'!$A4,'Round 4 Data'!$A$10:$A$147,'Round 4 Data'!I$10:I$147,0))/$D4 -> #VALUE! | J4: =(_xlfn.XLOOKUP('Summary Data'!$A4,'Round 1 Data'!$A$10:$A$143,'Round 1 Data'!J$10:J$144,0)+_xlfn.XLOOKUP('Summary Data'!$A4,'Round 2 Data'!$A$10:$A$146,'Round 2 Data'!J$10:J$146,0)+_xlfn.XLOOKUP('Summary Data'!$A4,'Round 3 Data'!$A$10:$A$145,'Round 3 Data'!J$10:J$145,0)+_xlfn.XLOOKUP('Summary Data'!$A4,'Round 4 Data'!$A$10:$A$147,'Round 4 Data'!J$10:J$147,0))/$D4 -> #VALUE! | K4: =(_xlfn.XLOOKUP('Summary Data'!$A4,'Round 1 Data'!$A$10:$A$143,'Round 1 Data'!K$10:K$144,0)+_xlfn.XLOOKUP('Summary Data'!$A4,'Round 2 Data'!$A$10:$A$146,'Round 2 Data'!K$10:K$146,0)+_xlfn.XLOOKUP('Summary Data'!$A4,'Round 3 Data'!$A$10:$A$145,'Round 3 Data'!K$10:K$145,0)+_xlfn.XLOOKUP('Summary Data'!$A4,'Round 4 Data'!$A$10:$A$147,'Round 4 Data'!K$10:K$147,0))/$D4 -> #VALUE! | L4: =(_xlfn.XLOOKUP('Summary Data'!$A4,'Round 1 Data'!$A$10:$A$143,'Round 1 Data'!L$10:L$144,0)+_xlfn.XLOOKUP('Summary Data'!$A4,'Round 2 Data'!$A$10:$A$146,'Round 2 Data'!L$10:L$146,0)+_xlfn.XLOOKUP('Summary Data'!$A4,'Round 3 Data'!$A$10:$A$145,'Round 3 Data'!L$10:L$145,0)+_xlfn.XLOOKUP('Summary Data'!$A4,'Round 4 Data'!$A$10:$A$147,'Round 4 Data'!L$10:L$147,0))/$D4 -> #VALUE! | ... S4: =(_xlfn.XLOOKUP('Summary Data'!$A4,'Round 1 Data'!$A$10:$A$143,'Round 1 Data'!S$10:S$144,0)+_xlfn.XLOOKUP('Summary Data'!$A4,'Round 2 Data'!$A$10:$A$146,'Round 2 Data'!S$10:S$146,0)+_xlfn.XLOOKUP('Summary Data'!$A4,'Round 3 Data'!$A$10:$A$145,'Round 3 Data'!S$10:S$145,0)+_xlfn.XLOOKUP('Summary Data'!$A4,'Round 4 Data'!$A$10:$A$147,'Round 4 Data'!S$10:S$147,0))/$D4 -> #VALUE! | T4: =(_xlfn.XLOOKUP('Summary Data'!$A4,'Round 1 Data'!$A$10:$A$143,'Round 1 Data'!U$10:U$144,0)+_xlfn.XLOOKUP('Summary Data'!$A4,'Round 2 Data'!$A$10:$A$146,'Round 2 Data'!U$10:U$146,0)+_xlfn.XLOOKUP('Summary Data'!$A4,'Round 3 Data'!$A$10:$A$145,'Round 3 Data'!U$10:U$145,0)+_xlfn.XLOOKUP('Summary Data'!$A4,'Round 4 Data'!$A$10:$A$147,'Round 4 Data'!U$10:U$147,0)) -> #VALUE!
A5: A. Cuthbert | B5: Wales | C5: Back Three | D5: =IF(_xlfn.XLOOKUP('Summary Data'!A5,'Round 1 Data'!$A$10:$A$143,'Round 1 Data'!$E$10:$E$144,0)=0,0,1)+IF(_xlfn.XLOOKUP('Summary Data'!A5,'Round 2 Data'!$A$10:$A$146,'Round 2 Data'!$E$10:$E$146,0)=0,0,1)+IF(_xlfn.XLOOKUP('Summary Data'!A5,'Round 3 Data'!$A$10:$A$145,'Round 3 Data'!$E$10:$E$145,0)=0,0,1)+IF(_xlfn.XLOOKUP('Summary Data'!A5,'Round 4 Data'!$A$10:$A$147,'Round 4 Data'!$E$10:$E$147,0)=0,0,1) -> #VALUE! | E5: =(_xlfn.XLOOKUP('Summary Data'!$A5,'Round 1 Data'!$A$10:$A$143,'Round 1 Data'!E$10:E$144,0)+_xlfn.XLOOKUP('Summary Data'!$A5,'Round 2 Data'!$A$10:$A$146,'Round 2 Data'!E$10:E$146,0)+_xlfn.XLOOKUP('Summary Data'!$A5,'Round 3 Data'!$A$10:$A$145,'Round 3 Data'!E$10:E$145,0)+_xlfn.XLOOKUP('Summary Data'!$A5,'Round 4 Data'!$A$10:$A$147,'Round 4 Data'!E$10:E$147,0))/$D5 -> #VALUE! | F5: =(_xlfn.XLOOKUP('Summary Data'!$A5,'Round 1 Data'!$A$10:$A$143,'Round 1 Data'!F$10:F$144,0)+_xlfn.XLOOKUP('Summary Data'!$A5,'Round 2 Data'!$A$10:$A$146,'Round 2 Data'!F$10:F$146,0)+_xlfn.XLOOKUP('Summary Data'!$A5,'Round 3 Data'!$A$10:$A$145,'Round 3 Data'!F$10:F$145,0)+_xlfn.XLOOKUP('Summary Data'!$A5,'Round 4 Data'!$A$10:$A$147,'Round 4 Data'!F$10:F$147,0))/$D5 -> #VALUE! | G5: =(_xlfn.XLOOKUP('Summary Data'!$A5,'Round 1 Data'!$A$10:$A$143,'Round 1 Data'!G$10:G$144,0)+_xlfn.XLOOKUP('Summary Data'!$A5,'Round 2 Data'!$A$10:$A$146,'Round 2 Data'!G$10:G$146,0)+_xlfn.XLOOKUP('Summary Data'!$A5,'Round 3 Data'!$A$10:$A$145,'Round 3 Data'!G$10:G$145,0)+_xlfn.XLOOKUP('Summary Data'!$A5,'Round 4 Data'!$A$10:$A$147,'Round 4 Data'!G$10:G$147,0))/$D5 -> #VALUE! | H5: =(_xlfn.XLOOKUP('Summary Data'!$A5,'Round 1 Data'!$A$10:$A$143,'Round 1 Data'!H$10:H$144,0)+_xlfn.XLOOKUP('Summary Data'!$A5,'Round 2 Data'!$A$10:$A$146,'Round 2 Data'!H$10:H$146,0)+_xlfn.XLOOKUP('Summary Data'!$A5,'Round 3 Data'!$A$10:$A$145,'Round 3 Data'!H$10:H$145,0)+_xlfn.XLOOKUP('Summary Data'!$A5,'Round 4 Data'!$A$10:$A$147,'Round 4 Data'!H$10:H$147,0))/$D5 -> #VALUE! | I5: =(_xlfn.XLOOKUP('Summary Data'!$A5,'Round 1 Data'!$A$10:$A$143,'Round 1 Data'!I$10:I$144,0)+_xlfn.XLOOKUP('Summary Data'!$A5,'Round 2 Data'!$A$10:$A$146,'Round 2 Data'!I$10:I$146,0)+_xlfn.XLOOKUP('Summary Data'!$A5,'Round 3 Data'!$A$10:$A$145,'Round 3 Data'!I$10:I$145,0)+_xlfn.XLOOKUP('Summary Data'!$A5,'Round 4 Data'!$A$10:$A$147,'Round 4 Data'!I$10:I$147,0))/$D5 -> #VALUE! | J5: =(_xlfn.XLOOKUP('Summary Data'!$A5,'Round 1 Data'!$A$10:$A$143,'Round 1 Data'!J$10:J$144,0)+_xlfn.XLOOKUP('Summary Data'!$A5,'Round 2 Data'!$A$10:$A$146,'Round 2 Data'!J$10:J$146,0)+_xlfn.XLOOKUP('Summary Data'!$A5,'Round 3 Data'!$A$10:$A$145,'Round 3 Data'!J$10:J$145,0)+_xlfn.XLOOKUP('Summary Data'!$A5,'Round 4 Data'!$A$10:$A$147,'Round 4 Data'!J$10:J$147,0))/$D5 -> #VALUE! | K5: =(_xlfn.XLOOKUP('Summary Data'!$A5,'Round 1 Data'!$A$10:$A$143,'Round 1 Data'!K$10:K$144,0)+_xlfn.XLOOKUP('Summary Data'!$A5,'Round 2 Data'!$A$10:$A$146,'Round 2 Data'!K$10:K$146,0)+_xlfn.XLOOKUP('Summary Data'!$A5,'Round 3 Data'!$A$10:$A$145,'Round 3 Data'!K$10:K$145,0)+_xlfn.XLOOKUP('Summary Data'!$A5,'Round 4 Data'!$A$10:$A$147,'Round 4 Data'!K$10:K$147,0))/$D5 -> #VALUE! | L5: =(_xlfn.XLOOKUP('Summary Data'!$A5,'Round 1 Data'!$A$10:$A$143,'Round 1 Data'!L$10:L$144,0)+_xlfn.XLOOKUP('Summary Data'!$A5,'Round 2 Data'!$A$10:$A$146,'Round 2 Data'!L$10:L$146,0)+_xlfn.XLOOKUP('Summary Data'!$A5,'Round 3 Data'!$A$10:$A$145,'Round 3 Data'!L$10:L$145,0)+_xlfn.XLOOKUP('Summary Data'!$A5,'Round 4 Data'!$A$10:$A$147,'Round 4 Data'!L$10:L$147,0))/$D5 -> #VALUE! | ... S5: =(_xlfn.XLOOKUP('Summary Data'!$A5,'Round 1 Data'!$A$10:$A$143,'Round 1 Data'!S$10:S$144,0)+_xlfn.XLOOKUP('Summary Data'!$A5,'Round 2 Data'!$A$10:$A$146,'Round 2 Data'!S$10:S$146,0)+_xlfn.XLOOKUP('Summary Data'!$A5,'Round 3 Data'!$A$10:$A$145,'Round 3 Data'!S$10:S$145,0)+_xlfn.XLOOKUP('Summary Data'!$A5,'Round 4 Data'!$A$10:$A$147,'Round 4 Data'!S$10:S$147,0))/$D5 -> #VALUE! | T5: =(_xlfn.XLOOKUP('Summary Data'!$A5,'Round 1 Data'!$A$10:$A$143,'Round 1 Data'!U$10:U$144,0)+_xlfn.XLOOKUP('Summary Data'!$A5,'Round 2 Data'!$A$10:$A$146,'Round 2 Data'!U$10:U$146,0)+_xlfn.XLOOKUP('Summary Data'!$A5,'Round 3 Data'!$A$10:$A$145,'Round 3 Data'!U$10:U$145,0)+_xlfn.XLOOKUP('Summary Data'!$A5,'Round 4 Data'!$A$10:$A$147,'Round 4 Data'!U$10:U$147,0)) -> #VALUE!
A6: R. Dyer | B6: Wales | C6: Back Three | D6: =IF(_xlfn.XLOOKUP('Summary Data'!A6,'Round 1 Data'!$A$10:$A$143,'Round 1 Data'!$E$10:$E$144,0)=0,0,1)+IF(_xlfn.XLOOKUP('Summary Data'!A6,'Round 2 Data'!$A$10:$A$146,'Round 2 Data'!$E$10:$E$146,0)=0,0,1)+IF(_xlfn.XLOOKUP('Summary Data'!A6,'Round 3 Data'!$A$10:$A$145,'Round 3 Data'!$E$10:$E$145,0)=0,0,1)+IF(_xlfn.XLOOKUP('Summary Data'!A6,'Round 4 Data'!$A$10:$A$147,'Round 4 Data'!$E$10:$E$147,0)=0,0,1) -> #VALUE! | E6: =(_xlfn.XLOOKUP('Summary Data'!$A6,'Round 1 Data'!$A$10:$A$143,'Round 1 Data'!E$10:E$144,0)+_xlfn.XLOOKUP('Summary Data'!$A6,'Round 2 Data'!$A$10:$A$146,'Round 2 Data'!E$10:E$146,0)+_xlfn.XLOOKUP('Summary Data'!$A6,'Round 3 Data'!$A$10:$A$145,'Round 3 Data'!E$10:E$145,0)+_xlfn.XLOOKUP('Summary Data'!$A6,'Round 4 Data'!$A$10:$A$147,'Round 4 Data'!E$10:E$147,0))/$D6 -> #VALUE! | F6: =(_xlfn.XLOOKUP('Summary Data'!$A6,'Round 1 Data'!$A$10:$A$143,'Round 1 Data'!F$10:F$144,0)+_xlfn.XLOOKUP('Summary Data'!$A6,'Round 2 Data'!$A$10:$A$146,'Round 2 Data'!F$10:F$146,0)+_xlfn.XLOOKUP('Summary Data'!$A6,'Round 3 Data'!$A$10:$A$145,'Round 3 Data'!F$10:F$145,0)+_xlfn.XLOOKUP('Summary Data'!$A6,'Round 4 Data'!$A$10:$A$147,'Round 4 Data'!F$10:F$147,0))/$D6 -> #VALUE! | G6: =(_xlfn.XLOOKUP('Summary Data'!$A6,'Round 1 Data'!$A$10:$A$143,'Round 1 Data'!G$10:G$144,0)+_xlfn.XLOOKUP('Summary Data'!$A6,'Round 2 Data'!$A$10:$A$146,'Round 2 Data'!G$10:G$146,0)+_xlfn.XLOOKUP('Summary Data'!$A6,'Round 3 Data'!$A$10:$A$145,'Round 3 Data'!G$10:G$145,0)+_xlfn.XLOOKUP('Summary Data'!$A6,'Round 4 Data'!$A$10:$A$147,'Round 4 Data'!G$10:G$147,0))/$D6 -> #VALUE! | H6: =(_xlfn.XLOOKUP('Summary Data'!$A6,'Round 1 Data'!$A$10:$A$143,'Round 1 Data'!H$10:H$144,0)+_xlfn.XLOOKUP('Summary Data'!$A6,'Round 2 Data'!$A$10:$A$146,'Round 2 Data'!H$10:H$146,0)+_xlfn.XLOOKUP('Summary Data'!$A6,'Round 3 Data'!$A$10:$A$145,'Round 3 Data'!H$10:H$145,0)+_xlfn.XLOOKUP('Summary Data'!$A6,'Round 4 Data'!$A$10:$A$147,'Round 4 Data'!H$10:H$147,0))/$D6 -> #VALUE! | I6: =(_xlfn.XLOOKUP('Summary Data'!$A6,'Round 1 Data'!$A$10:$A$143,'Round 1 Data'!I$10:I$144,0)+_xlfn.XLOOKUP('Summary Data'!$A6,'Round 2 Data'!$A$10:$A$146,'Round 2 Data'!I$10:I$146,0)+_xlfn.XLOOKUP('Summary Data'!$A6,'Round 3 Data'!$A$10:$A$145,'Round 3 Data'!I$10:I$145,0)+_xlfn.XLOOKUP('Summary Data'!$A6,'Round 4 Data'!$A$10:$A$147,'Round 4 Data'!I$10:I$147,0))/$D6 -> #VALUE! | J6: =(_xlfn.XLOOKUP('Summary Data'!$A6,'Round 1 Data'!$A$10:$A$143,'Round 1 Data'!J$10:J$144,0)+_xlfn.XLOOKUP('Summary Data'!$A6,'Round 2 Data'!$A$10:$A$146,'Round 2 Data'!J$10:J$146,0)+_xlfn.XLOOKUP('Summary Data'!$A6,'Round 3 Data'!$A$10:$A$145,'Round 3 Data'!J$10:J$145,0)+_xlfn.XLOOKUP('Summary Data'!$A6,'Round 4 Data'!$A$10:$A$147,'Round 4 Data'!J$10:J$147,0))/$D6 -> #VALUE! | K6: =(_xlfn.XLOOKUP('Summary Data'!$A6,'Round 1 Data'!$A$10:$A$143,'Round 1 Data'!K$10:K$144,0)+_xlfn.XLOOKUP('Summary Data'!$A6,'Round 2 Data'!$A$10:$A$146,'Round 2 Data'!K$10:K$146,0)+_xlfn.XLOOKUP('Summary Data'!$A6,'Round 3 Data'!$A$10:$A$145,'Round 3 Data'!K$10:K$145,0)+_xlfn.XLOOKUP('Summary Data'!$A6,'Round 4 Data'!$A$10:$A$147,'Round 4 Data'!K$10:K$147,0))/$D6 -> #VALUE! | L6: =(_xlfn.XLOOKUP('Summary Data'!$A6,'Round 1 Data'!$A$10:$A$143,'Round 1 Data'!L$10:L$144,0)+_xlfn.XLOOKUP('Summary Data'!$A6,'Round 2 Data'!$A$10:$A$146,'Round 2 Data'!L$10:L$146,0)+_xlfn.XLOOKUP('Summary Data'!$A6,'Round 3 Data'!$A$10:$A$145,'Round 3 Data'!L$10:L$145,0)+_xlfn.XLOOKUP('Summary Data'!$A6,'Round 4 Data'!$A$10:$A$147,'Round 4 Data'!L$10:L$147,0))/$D6 -> #VALUE! | ... S6: =(_xlfn.XLOOKUP('Summary Data'!$A6,'Round 1 Data'!$A$10:$A$143,'Round 1 Data'!S$10:S$144,0)+_xlfn.XLOOKUP('Summary Data'!$A6,'Round 2 Data'!$A$10:$A$146,'Round 2 Data'!S$10:S$146,0)+_xlfn.XLOOKUP('Summary Data'!$A6,'Round 3 Data'!$A$10:$A$145,'Round 3 Data'!S$10:S$145,0)+_xlfn.XLOOKUP('Summary Data'!$A6,'Round 4 Data'!$A$10:$A$147,'Round 4 Data'!S$10:S$147,0))/$D6 -> #VALUE! | T6: =(_xlfn.XLOOKUP('Summary Data'!$A6,'Round 1 Data'!$A$10:$A$143,'Round 1 Data'!U$10:U$144,0)+_xlfn.XLOOKUP('Summary Data'!$A6,'Round 2 Data'!$A$10:$A$146,'Round 2 Data'!U$10:U$146,0)+_xlfn.XLOOKUP('Summary Data'!$A6,'Round 3 Data'!$A$10:$A$145,'Round 3 Data'!U$10:U$145,0)+_xlfn.XLOOKUP('Summary Data'!$A6,'Round 4 Data'!$A$10:$A$147,'Round 4 Data'!U$10:U$147,0)) -> #VALUE!
A7: L. Williams | B7: Wales | C7: Back Three | D7: =IF(_xlfn.XLOOKUP('Summary Data'!A7,'Round 1 Data'!$A$10:$A$143,'Round 1 Data'!$E$10:$E$144,0)=0,0,1)+IF(_xlfn.XLOOKUP('Summary Data'!A7,'Round 2 Data'!$A$10:$A$146,'Round 2 Data'!$E$10:$E$146,0)=0,0,1)+IF(_xlfn.XLOOKUP('Summary Data'!A7,'Round 3 Data'!$A$10:$A$145,'Round 3 Data'!$E$10:$E$145,0)=0,0,1)+IF(_xlfn.XLOOKUP('Summary Data'!A7,'Round 4 Data'!$A$10:$A$147,'Round 4 Data'!$E$10:$E$147,0)=0,0,1) -> #VALUE! | E7: =(_xlfn.XLOOKUP('Summary Data'!$A7,'Round 1 Data'!$A$10:$A$143,'Round 1 Data'!E$10:E$144,0)+_xlfn.XLOOKUP('Summary Data'!$A7,'Round 2 Data'!$A$10:$A$146,'Round 2 Data'!E$10:E$146,0)+_xlfn.XLOOKUP('Summary Data'!$A7,'Round 3 Data'!$A$10:$A$145,'Round 3 Data'!E$10:E$145,0)+_xlfn.XLOOKUP('Summary Data'!$A7,'Round 4 Data'!$A$10:$A$147,'Round 4 Data'!E$10:E$147,0))/$D7 -> #VALUE! | F7: =(_xlfn.XLOOKUP('Summary Data'!$A7,'Round 1 Data'!$A$10:$A$143,'Round 1 Data'!F$10:F$144,0)+_xlfn.XLOOKUP('Summary Data'!$A7,'Round 2 Data'!$A$10:$A$146,'Round 2 Data'!F$10:F$146,0)+_xlfn.XLOOKUP('Summary Data'!$A7,'Round 3 Data'!$A$10:$A$145,'Round 3 Data'!F$10:F$145,0)+_xlfn.XLOOKUP('Summary Data'!$A7,'Round 4 Data'!$A$10:$A$147,'Round 4 Data'!F$10:F$147,0))/$D7 -> #VALUE! | G7: =(_xlfn.XLOOKUP('Summary Data'!$A7,'Round 1 Data'!$A$10:$A$143,'Round 1 Data'!G$10:G$144,0)+_xlfn.XLOOKUP('Summary Data'!$A7,'Round 2 Data'!$A$10:$A$146,'Round 2 Data'!G$10:G$146,0)+_xlfn.XLOOKUP('Summary Data'!$A7,'Round 3 Data'!$A$10:$A$145,'Round 3 Data'!G$10:G$145,0)+_xlfn.XLOOKUP('Summary Data'!$A7,'Round 4 Data'!$A$10:$A$147,'Round 4 Data'!G$10:G$147,0))/$D7 -> #VALUE! | H7: =(_xlfn.XLOOKUP('Summary Data'!$A7,'Round 1 Data'!$A$10:$A$143,'Round 1 Data'!H$10:H$144,0)+_xlfn.XLOOKUP('Summary Data'!$A7,'Round 2 Data'!$A$10:$A$146,'Round 2 Data'!H$10:H$146,0)+_xlfn.XLOOKUP('Summary Data'!$A7,'Round 3 Data'!$A$10:$A$145,'Round 3 Data'!H$10:H$145,0)+_xlfn.XLOOKUP('Summary Data'!$A7,'Round 4 Data'!$A$10:$A$147,'Round 4 Data'!H$10:H$147,0))/$D7 -> #VALUE! | I7: =(_xlfn.XLOOKUP('Summary Data'!$A7,'Round 1 Data'!$A$10:$A$143,'Round 1 Data'!I$10:I$144,0)+_xlfn.XLOOKUP('Summary Data'!$A7,'Round 2 Data'!$A$10:$A$146,'Round 2 Data'!I$10:I$146,0)+_xlfn.XLOOKUP('Summary Data'!$A7,'Round 3 Data'!$A$10:$A$145,'Round 3 Data'!I$10:I$145,0)+_xlfn.XLOOKUP('Summary Data'!$A7,'Round 4 Data'!$A$10:$A$147,'Round 4 Data'!I$10:I$147,0))/$D7 -> #VALUE! | J7: =(_xlfn.XLOOKUP('Summary Data'!$A7,'Round 1 Data'!$A$10:$A$143,'Round 1 Data'!J$10:J$144,0)+_xlfn.XLOOKUP('Summary Data'!$A7,'Round 2 Data'!$A$10:$A$146,'Round 2 Data'!J$10:J$146,0)+_xlfn.XLOOKUP('Summary Data'!$A7,'Round 3 Data'!$A$10:$A$145,'Round 3 Data'!J$10:J$145,0)+_xlfn.XLOOKUP('Summary Data'!$A7,'Round 4 Data'!$A$10:$A$147,'Round 4 Data'!J$10:J$147,0))/$D7 -> #VALUE! | K7: =(_xlfn.XLOOKUP('Summary Data'!$A7,'Round 1 Data'!$A$10:$A$143,'Round 1 Data'!K$10:K$144,0)+_xlfn.XLOOKUP('Summary Data'!$A7,'Round 2 Data'!$A$10:$A$146,'Round 2 Data'!K$10:K$146,0)+_xlfn.XLOOKUP('Summary Data'!$A7,'Round 3 Data'!$A$10:$A$145,'Round 3 Data'!K$10:K$145,0)+_xlfn.XLOOKUP('Summary Data'!$A7,'Round 4 Data'!$A$10:$A$147,'Round 4 Data'!K$10:K$147,0))/$D7 -> #VALUE! | L7: =(_xlfn.XLOOKUP('Summary Data'!$A7,'Round 1 Data'!$A$10:$A$143,'Round 1 Data'!L$10:L$144,0)+_xlfn.XLOOKUP('Summary Data'!$A7,'Round 2 Data'!$A$10:$A$146,'Round 2 Data'!L$10:L$146,0)+_xlfn.XLOOKUP('Summary Data'!$A7,'Round 3 Data'!$A$10:$A$145,'Round 3 Data'!L$10:L$145,0)+_xlfn.XLOOKUP('Summary Data'!$A7,'Round 4 Data'!$A$10:$A$147,'Round 4 Data'!L$10:L$147,0))/$D7 -> #VALUE! | ... S7: =(_xlfn.XLOOKUP('Summary Data'!$A7,'Round 1 Data'!$A$10:$A$143,'Round 1 Data'!S$10:S$144,0)+_xlfn.XLOOKUP('Summary Data'!$A7,'Round 2 Data'!$A$10:$A$146,'Round 2 Data'!S$10:S$146,0)+_xlfn.XLOOKUP('Summary Data'!$A7,'Round 3 Data'!$A$10:$A$145,'Round 3 Data'!S$10:S$145,0)+_xlfn.XLOOKUP('Summary Data'!$A7,'Round 4 Data'!$A$10:$A$147,'Round 4 Data'!S$10:S$147,0))/$D7 -> #VALUE! | T7: =(_xlfn.XLOOKUP('Summary Data'!$A7,'Round 1 Data'!$A$10:$A$143,'Round 1 Data'!U$10:U$144,0)+_xlfn.XLOOKUP('Summary Data'!$A7,'Round 2 Data'!$A$10:$A$146,'Round 2 Data'!U$10:U$146,0)+_xlfn.XLOOKUP('Summary Data'!$A7,'Round 3 Data'!$A$10:$A$145,'Round 3 Data'!U$10:U$145,0)+_xlfn.XLOOKUP('Summary Data'!$A7,'Round 4 Data'!$A$10:$A$147,'Round 4 Data'!U$10:U$147,0)) -> #VALUE!
A8: J. Hawkins | B8: Wales | C8: Centre | D8: =IF(_xlfn.XLOOKUP('Summary Data'!A8,'Round 1 Data'!$A$10:$A$143,'Round 1 Data'!$E$10:$E$144,0)=0,0,1)+IF(_xlfn.XLOOKUP('Summary Data'!A8,'Round 2 Data'!$A$10:$A$146,'Round 2 Data'!$E$10:$E$146,0)=0,0,1)+IF(_xlfn.XLOOKUP('Summary Data'!A8,'Round 3 Data'!$A$10:$A$145,'Round 3 Data'!$E$10:$E$145,0)=0,0,1)+IF(_xlfn.XLOOKUP('Summary Data'!A8,'Round 4 Data'!$A$10:$A$147,'Round 4 Data'!$E$10:$E$147,0)=0,0,1) -> #VALUE! | E8: =(_xlfn.XLOOKUP('Summary Data'!$A8,'Round 1 Data'!$A$10:$A$143,'Round 1 Data'!E$10:E$144,0)+_xlfn.XLOOKUP('Summary Data'!$A8,'Round 2 Data'!$A$10:$A$146,'Round 2 Data'!E$10:E$146,0)+_xlfn.XLOOKUP('Summary Data'!$A8,'Round 3 Data'!$A$10:$A$145,'Round 3 Data'!E$10:E$145,0)+_xlfn.XLOOKUP('Summary Data'!$A8,'Round 4 Data'!$A$10:$A$147,'Round 4 Data'!E$10:E$147,0))/$D8 -> #VALUE! | F8: =(_xlfn.XLOOKUP('Summary Data'!$A8,'Round 1 Data'!$A$10:$A$143,'Round 1 Data'!F$10:F$144,0)+_xlfn.XLOOKUP('Summary Data'!$A8,'Round 2 Data'!$A$10:$A$146,'Round 2 Data'!F$10:F$146,0)+_xlfn.XLOOKUP('Summary Data'!$A8,'Round 3 Data'!$A$10:$A$145,'Round 3 Data'!F$10:F$145,0)+_xlfn.XLOOKUP('Summary Data'!$A8,'Round 4 Data'!$A$10:$A$147,'Round 4 Data'!F$10:F$147,0))/$D8 -> #VALUE! | G8: =(_xlfn.XLOOKUP('Summary Data'!$A8,'Round 1 Data'!$A$10:$A$143,'Round 1 Data'!G$10:G$144,0)+_xlfn.XLOOKUP('Summary Data'!$A8,'Round 2 Data'!$A$10:$A$146,'Round 2 Data'!G$10:G$146,0)+_xlfn.XLOOKUP('Summary Data'!$A8,'Round 3 Data'!$A$10:$A$145,'Round 3 Data'!G$10:G$145,0)+_xlfn.XLOOKUP('Summary Data'!$A8,'Round 4 Data'!$A$10:$A$147,'Round 4 Data'!G$10:G$147,0))/$D8 -> #VALUE! | H8: =(_xlfn.XLOOKUP('Summary Data'!$A8,'Round 1 Data'!$A$10:$A$143,'Round 1 Data'!H$10:H$144,0)+_xlfn.XLOOKUP('Summary Data'!$A8,'Round 2 Data'!$A$10:$A$146,'Round 2 Data'!H$10:H$146,0)+_xlfn.XLOOKUP('Summary Data'!$A8,'Round 3 Data'!$A$10:$A$145,'Round 3 Data'!H$10:H$145,0)+_xlfn.XLOOKUP('Summary Data'!$A8,'Round 4 Data'!$A$10:$A$147,'Round 4 Data'!H$10:H$147,0))/$D8 -> #VALUE! | I8: =(_xlfn.XLOOKUP('Summary Data'!$A8,'Round 1 Data'!$A$10:$A$143,'Round 1 Data'!I$10:I$144,0)+_xlfn.XLOOKUP('Summary Data'!$A8,'Round 2 Data'!$A$10:$A$146,'Round 2 Data'!I$10:I$146,0)+_xlfn.XLOOKUP('Summary Data'!$A8,'Round 3 Data'!$A$10:$A$145,'Round 3 Data'!I$10:I$145,0)+_xlfn.XLOOKUP('Summary Data'!$A8,'Round 4 Data'!$A$10:$A$147,'Round 4 Data'!I$10:I$147,0))/$D8 -> #VALUE! | J8: =(_xlfn.XLOOKUP('Summary Data'!$A8,'Round 1 Data'!$A$10:$A$143,'Round 1 Data'!J$10:J$144,0)+_xlfn.XLOOKUP('Summary Data'!$A8,'Round 2 Data'!$A$10:$A$146,'Round 2 Data'!J$10:J$146,0)+_xlfn.XLOOKUP('Summary Data'!$A8,'Round 3 Data'!$A$10:$A$145,'Round 3 Data'!J$10:J$145,0)+_xlfn.XLOOKUP('Summary Data'!$A8,'Round 4 Data'!$A$10:$A$147,'Round 4 Data'!J$10:J$147,0))/$D8 -> #VALUE! | K8: =(_xlfn.XLOOKUP('Summary Data'!$A8,'Round 1 Data'!$A$10:$A$143,'Round 1 Data'!K$10:K$144,0)+_xlfn.XLOOKUP('Summary Data'!$A8,'Round 2 Data'!$A$10:$A$146,'Round 2 Data'!K$10:K$146,0)+_xlfn.XLOOKUP('Summary Data'!$A8,'Round 3 Data'!$A$10:$A$145,'Round 3 Data'!K$10:K$145,0)+_xlfn.XLOOKUP('Summary Data'!$A8,'Round 4 Data'!$A$10:$A$147,'Round 4 Data'!K$10:K$147,0))/$D8 -> #VALUE! | L8: =(_xlfn.XLOOKUP('Summary Data'!$A8,'Round 1 Data'!$A$10:$A$143,'Round 1 Data'!L$10:L$144,0)+_xlfn.XLOOKUP('Summary Data'!$A8,'Round 2 Data'!$A$10:$A$146,'Round 2 Data'!L$10:L$146,0)+_xlfn.XLOOKUP('Summary Data'!$A8,'Round 3 Data'!$A$10:$A$145,'Round 3 Data'!L$10:L$145,0)+_xlfn.XLOOKUP('Summary Data'!$A8,'Round 4 Data'!$A$10:$A$147,'Round 4 Data'!L$10:L$147,0))/$D8 -> #VALUE! | ... S8: =(_xlfn.XLOOKUP('Summary Data'!$A8,'Round 1 Data'!$A$10:$A$143,'Round 1 Data'!S$10:S$144,0)+_xlfn.XLOOKUP('Summary Data'!$A8,'Round 2 Data'!$A$10:$A$146,'Round 2 Data'!S$10:S$146,0)+_xlfn.XLOOKUP('Summary Data'!$A8,'Round 3 Data'!$A$10:$A$145,'Round 3 Data'!S$10:S$145,0)+_xlfn.XLOOKUP('Summary Data'!$A8,'Round 4 Data'!$A$10:$A$147,'Round 4 Data'!S$10:S$147,0))/$D8 -> #VALUE! | T8: =(_xlfn.XLOOKUP('Summary Data'!$A8,'Round 1 Data'!$A$10:$A$143,'Round 1 Data'!U$10:U$144,0)+_xlfn.XLOOKUP('Summary Data'!$A8,'Round 2 Data'!$A$10:$A$146,'Round 2 Data'!U$10:U$146,0)+_xlfn.XLOOKUP('Summary Data'!$A8,'Round 3 Data'!$A$10:$A$145,'Round 3 Data'!U$10:U$145,0)+_xlfn.XLOOKUP('Summary Data'!$A8,'Round 4 Data'!$A$10:$A$147,'Round 4 Data'!U$10:U$147,0)) -> #VALUE!
A9: G. North | B9: Wales | C9: Centre | D9: =IF(_xlfn.XLOOKUP('Summary Data'!A9,'Round 1 Data'!$A$10:$A$143,'Round 1 Data'!$E$10:$E$144,0)=0,0,1)+IF(_xlfn.XLOOKUP('Summary Data'!A9,'Round 2 Data'!$A$10:$A$146,'Round 2 Data'!$E$10:$E$146,0)=0,0,1)+IF(_xlfn.XLOOKUP('Summary Data'!A9,'Round 3 Data'!$A$10:$A$145,'Round 3 Data'!$E$10:$E$145,0)=0,0,1)+IF(_xlfn.XLOOKUP('Summary Data'!A9,'Round 4 Data'!$A$10:$A$147,'Round 4 Data'!$E$10:$E$147,0)=0,0,1) -> #VALUE! | E9: =(_xlfn.XLOOKUP('Summary Data'!$A9,'Round 1 Data'!$A$10:$A$143,'Round 1 Data'!E$10:E$144,0)+_xlfn.XLOOKUP('Summary Data'!$A9,'Round 2 Data'!$A$10:$A$146,'Round 2 Data'!E$10:E$146,0)+_xlfn.XLOOKUP('Summary Data'!$A9,'Round 3 Data'!$A$10:$A$145,'Round 3 Data'!E$10:E$145,0)+_xlfn.XLOOKUP('Summary Data'!$A9,'Round 4 Data'!$A$10:$A$147,'Round 4 Data'!E$10:E$147,0))/$D9 -> #VALUE! | F9: =(_xlfn.XLOOKUP('Summary Data'!$A9,'Round 1 Data'!$A$10:$A$143,'Round 1 Data'!F$10:F$144,0)+_xlfn.XLOOKUP('Summary Data'!$A9,'Round 2 Data'!$A$10:$A$146,'Round 2 Data'!F$10:F$146,0)+_xlfn.XLOOKUP('Summary Data'!$A9,'Round 3 Data'!$A$10:$A$145,'Round 3 Data'!F$10:F$145,0)+_xlfn.XLOOKUP('Summary Data'!$A9,'Round 4 Data'!$A$10:$A$147,'Round 4 Data'!F$10:F$147,0))/$D9 -> #VALUE! | G9: =(_xlfn.XLOOKUP('Summary Data'!$A9,'Round 1 Data'!$A$10:$A$143,'Round 1 Data'!G$10:G$144,0)+_xlfn.XLOOKUP('Summary Data'!$A9,'Round 2 Data'!$A$10:$A$146,'Round 2 Data'!G$10:G$146,0)+_xlfn.XLOOKUP('Summary Data'!$A9,'Round 3 Data'!$A$10:$A$145,'Round 3 Data'!G$10:G$145,0)+_xlfn.XLOOKUP('Summary Data'!$A9,'Round 4 Data'!$A$10:$A$147,'Round 4 Data'!G$10:G$147,0))/$D9 -> #VALUE! | H9: =(_xlfn.XLOOKUP('Summary Data'!$A9,'Round 1 Data'!$A$10:$A$143,'Round 1 Data'!H$10:H$144,0)+_xlfn.XLOOKUP('Summary Data'!$A9,'Round 2 Data'!$A$10:$A$146,'Round 2 Data'!H$10:H$146,0)+_xlfn.XLOOKUP('Summary Data'!$A9,'Round 3 Data'!$A$10:$A$145,'Round 3 Data'!H$10:H$145,0)+_xlfn.XLOOKUP('Summary Data'!$A9,'Round 4 Data'!$A$10:$A$147,'Round 4 Data'!H$10:H$147,0))/$D9 -> #VALUE! | I9: =(_xlfn.XLOOKUP('Summary Data'!$A9,'Round 1 Data'!$A$10:$A$143,'Round 1 Data'!I$10:I$144,0)+_xlfn.XLOOKUP('Summary Data'!$A9,'Round 2 Data'!$A$10:$A$146,'Round 2 Data'!I$10:I$146,0)+_xlfn.XLOOKUP('Summary Data'!$A9,'Round 3 Data'!$A$10:$A$145,'Round 3 Data'!I$10:I$145,0)+_xlfn.XLOOKUP('Summary Data'!$A9,'Round 4 Data'!$A$10:$A$147,'Round 4 Data'!I$10:I$147,0))/$D9 -> #VALUE! | J9: =(_xlfn.XLOOKUP('Summary Data'!$A9,'Round 1 Data'!$A$10:$A$143,'Round 1 Data'!J$10:J$144,0)+_xlfn.XLOOKUP('Summary Data'!$A9,'Round 2 Data'!$A$10:$A$146,'Round 2 Data'!J$10:J$146,0)+_xlfn.XLOOKUP('Summary Data'!$A9,'Round 3 Data'!$A$10:$A$145,'Round 3 Data'!J$10:J$145,0)+_xlfn.XLOOKUP('Summary Data'!$A9,'Round 4 Data'!$A$10:$A$147,'Round 4 Data'!J$10:J$147,0))/$D9 -> #VALUE! | K9: =(_xlfn.XLOOKUP('Summary Data'!$A9,'Round 1 Data'!$A$10:$A$143,'Round 1 Data'!K$10:K$144,0)+_xlfn.XLOOKUP('Summary Data'!$A9,'Round 2 Data'!$A$10:$A$146,'Round 2 Data'!K$10:K$146,0)+_xlfn.XLOOKUP('Summary Data'!$A9,'Round 3 Data'!$A$10:$A$145,'Round 3 Data'!K$10:K$145,0)+_xlfn.XLOOKUP('Summary Data'!$A9,'Round 4 Data'!$A$10:$A$147,'Round 4 Data'!K$10:K$147,0))/$D9 -> #VALUE! | L9: =(_xlfn.XLOOKUP('Summary Data'!$A9,'Round 1 Data'!$A$10:$A$143,'Round 1 Data'!L$10:L$144,0)+_xlfn.XLOOKUP('Summary Data'!$A9,'Round 2 Data'!$A$10:$A$146,'Round 2 Data'!L$10:L$146,0)+_xlfn.XLOOKUP('Summary Data'!$A9,'Round 3 Data'!$A$10:$A$145,'Round 3 Data'!L$10:L$145,0)+_xlfn.XLOOKUP('Summary Data'!$A9,'Round 4 Data'!$A$10:$A$147,'Round 4 Data'!L$10:L$147,0))/$D9 -> #VALUE! | ... S9: =(_xlfn.XLOOKUP('Summary Data'!$A9,'Round 1 Data'!$A$10:$A$143,'Round 1 Data'!S$10:S$144,0)+_xlfn.XLOOKUP('Summary Data'!$A9,'Round 2 Data'!$A$10:$A$146,'Round 2 Data'!S$10:S$146,0)+_xlfn.XLOOKUP('Summary Data'!$A9,'Round 3 Data'!$A$10:$A$145,'Round 3 Data'!S$10:S$145,0)+_xlfn.XLOOKUP('Summary Data'!$A9,'Round 4 Data'!$A$10:$A$147,'Round 4 Data'!S$10:S$147,0))/$D9 -> #VALUE! | T9: =(_xlfn.XLOOKUP('Summary Data'!$A9,'Round 1 Data'!$A$10:$A$143,'Round 1 Data'!U$10:U$144,0)+_xlfn.XLOOKUP('Summary Data'!$A9,'Round 2 Data'!$A$10:$A$146,'Round 2 Data'!U$10:U$146,0)+_xlfn.XLOOKUP('Summary Data'!$A9,'Round 3 Data'!$A$10:$A$145,'Round 3 Data'!U$10:U$145,0)+_xlfn.XLOOKUP('Summary Data'!$A9,'Round 4 Data'!$A$10:$A$147,'Round 4 Data'!U$10:U$147,0)) -> #VALUE!
