Workbook

Sheet Raw Data ---->

Sheet Round 1 Data
B2: Scotland | C2: Win | E2: Wales | F2: 10 | G2: 34 | H2: Ireland
B3: Wales | C3: Loss | E3: England | F3: 23 | G3: 29 | H3: Scotland
B4: Ireland | C4: Win | E4: Italy | F4: 24 | G4: 29 | H4: France
B5: England | C5: Loss
B6: France | C6: Win
B7: Italy | C7: Loss
A9: Name | B9: Nation | C9: Position | D9: Win/Loss | E9: Time Played | F9: Tackles | G9: Dominant Tackles | H9: Line Breaks | I9: Metres Carried | J9: 50-22 | K9: Lineout Steal | L9: Breakdown Steal | M9: Try | N9: Assists | O9: Conversion | P9: Penalty | Q9: Drop Goal | R9: Yellow Card | S9: Red Card | T9: Game Total | U9: MoM
A10: J. Adams | B10: {=_xlfn.XLOOKUP(A10,'Player List'!$A$2:$A$177,'Player List'!$B$2:$C$177)} | C10: Back Three | D10: =_xlfn.XLOOKUP(B10,$B$2:$B$7,$C$2:$C$7) | E10: 80 | F10: 3 | G10: 3 | I10: 36 | T10: 31.2
A11: A. Cuthbert | B11: {=_xlfn.XLOOKUP(A11,'Player List'!$A$2:$A$177,'Player List'!$B$2:$C$177)} | C11: Back Three | D11: =_xlfn.XLOOKUP(B11,$B$2:$B$7,$C$2:$C$7) | E11: 12 | F11: 1 | I11: 28 | T11: 6.6
A12: R. Dyer | B12: {=_xlfn.XLOOKUP(A12,'Player List'!$A$2:$A$177,'Player List'!$B$2:$C$177)} | C12: Back Three | D12: =_xlfn.XLOOKUP(B12,$B$2:$B$7,$C$2:$C$7) | E12: 68 | F12: 4 | H12: 2 | I12: 107 | T12: 39.4
A13: L. Williams | B13: {=_xlfn.XLOOKUP(A13,'Player List'!$A$2:$A$177,'Player List'!$B$2:$C$177)} | C13: Back Three | D13: =_xlfn.XLOOKUP(B13,$B$2:$B$7,$C$2:$C$7) | E13: 70 | F13: 2 | H13: 2 | I13: 108 | L13: 1 | M13: 1 | R13: 1 | T13: 54.6
A14: J. Hawkins | B14: {=_xlfn.XLOOKUP(A14,'Player List'!$A$2:$A$177,'Player List'!$B$2:$C$177)} | C14: Centre | D14: =_xlfn.XLOOKUP(B14,$B$2:$B$7,$C$2:$C$7) | E14: 80 | F14: 6 | G14: 1 | H14: 1 | I14: 75 | T14: 35
A15: G. North | B15: {=_xlfn.XLOOKUP(A15,'Player List'!$A$2:$A$177,'Player List'!$B$2:$C$177)} | C15: Centre | D15: =_xlfn.XLOOKUP(B15,$B$2:$B$7,$C$2:$C$7) | E15: 80 | F15: 4 | I15: 58 | T15: 15.6
A16: D. Biggar | B16: {=_xlfn.XLOOKUP(A16,'Player List'!$A$2:$A$177,'Player List'!$B$2:$C$177)} | C16: Fly Half | D16: =_xlfn.XLOOKUP(B16,$B$2:$B$7,$C$2:$C$7) | E16: 67 | F16: 9 | H16: 1 | I16: 35 | N16: 1 | O16: 1 | P16: 1 | T16: 37
A17: O. Williams | B17: {=_xlfn.XLOOKUP(A17,'Player List'!$A$2:$A$177,'Player List'!$B$2:$C$177)} | C17: Fly Half | D17: =_xlfn.XLOOKUP(B17,$B$2:$B$7,$C$2:$C$7) | E17: 13 | F17: 1 | I17: 4 | T17: 1.8
A18: R. Webb | B18: {=_xlfn.XLOOKUP(A18,'Player List'!$A$2:$A$177,'Player List'!$B$2:$C$177)} | C18: Scrum Half | D18: =_xlfn.XLOOKUP(B18,$B$2:$B$7,$C$2:$C$7) | E18: 17 | F18: 2 | G18: 1 | I18: 1 | T18: 9.2
A19: T. Williams | B19: {=_xlfn.XLOOKUP(A19,'Player List'!$A$2:$A$177,'Player List'!$B$2:$C$177)} | C19: Scrum Half | D19: =_xlfn.XLOOKUP(B19,$B$2:$B$7,$C$2:$C$7) | E19: 63 | F19: 6 | I19: 19 | T19: 9.8
A20: T. Faletau | B20: {=_xlfn.XLOOKUP(A20,'Player List'!$A$2:$A$177,'Player List'!$B$2:$C$177)} | C20: Back Row | D20: =_xlfn.XLOOKUP(B20,$B$2:$B$7,$C$2:$C$7) | E20: 80 | F20: 20 | G20: 1 | I20: 49 | T20: 36.8
A21: J. Morgan | B21: {=_xlfn.XLOOKUP(A21,'Player List'!$A$2:$A$177,'Player List'!$B$2:$C$177)} | C21: Back Row | D21: =_xlfn.XLOOKUP(B21,$B$2:$B$7,$C$2:$C$7) | E21: 80 | F21: 14 | G21: 3 | I21: 43 | L21: 1 | T21: 50.6
A22: T. Reffell | B22: {=_xlfn.XLOOKUP(A22,'Player List'!$A$2:$A$177,'Player List'!$B$2:$C$177)} | C22: Back Row | D22: =_xlfn.XLOOKUP(B22,$B$2:$B$7,$C$2:$C$7) | E22: 26 | F22: 8 | T22: 8
A23: J. Tipuric | B23: {=_xlfn.XLOOKUP(A23,'Player List'!$A$2:$A$177,'Player List'!$B$2:$C$177)} | C23: Back Row | D23: =_xlfn.XLOOKUP(B23,$B$2:$B$7,$C$2:$C$7) | E23: 54 | F23: 11 | G23: 3 | I23: 18 | T23: 35.6
A24: A. Beard | B24: {=_xlfn.XLOOKUP(A24,'Player List'!$A$2:$A$177,'Player List'!$B$2:$C$177)} | C24: Second Row | D24: =_xlfn.XLOOKUP(B24,$B$2:$B$7,$C$2:$C$7) | E24: 80 | F24: 13 | G24: 2 | I24: 7 | T24: 28.4
A25: D. Jenkins | B25: {=_xlfn.XLOOKUP(A25,'Player List'!$A$2:$A$177,'Player List'!$B$2:$C$177)} | C25: Second Row | D25: =_xlfn.XLOOKUP(B25,$B$2:$B$7,$C$2:$C$7) | E25: 19 | F25: 3 | I25: 35 | T25: 10
A26: A. Jones | B26: {=_xlfn.XLOOKUP(A26,'Player List'!$A$2:$A$177,'Player List'!$B$2:$C$177)} | C26: Second Row | D26: =_xlfn.XLOOKUP(B26,$B$2:$B$7,$C$2:$C$7) | E26: 61 | F26: 10 | G26: 1 | I26: 29 | T26: 22.8
A27: R. Carre | B27: {=_xlfn.XLOOKUP(A27,'Player List'!$A$2:$A$177,'Player List'!$B$2:$C$177)} | C27: Prop | D27: =_xlfn.XLOOKUP(B27,$B$2:$B$7,$C$2:$C$7) | E27: 26 | F27: 3 | L27: 1 | T27: 10
A28: T. Francis | B28: {=_xlfn.XLOOKUP(A28,'Player List'!$A$2:$A$177,'Player List'!$B$2:$C$177)} | C28: Prop | D28: =_xlfn.XLOOKUP(B28,$B$2:$B$7,$C$2:$C$7) | E28: 40 | F28: 9 | G28: 3 | T28: 30
A29: D. Lewis | B29: {=_xlfn.XLOOKUP(A29,'Player List'!$A$2:$A$177,'Player List'!$B$2:$C$177)} | C29: Prop | D29: =_xlfn.XLOOKUP(B29,$B$2:$B$7,$C$2:$C$7) | E29: 40 | F29: 5 | I29: 7 | T29: 6.4
A30: G. Thomas | B30: {=_xlfn.XLOOKUP(A30,'Player List'!$A$2:$A$177,'Player List'!$B$2:$C$177)} | C30: Prop | D30: =_xlfn.XLOOKUP(B30,$B$2:$B$7,$C$2:$C$7) | E30: 54 | F30: 11 | G30: 2 | I30: 21 | T30: 29.2
A31: S. Baldwin | B31: {=_xlfn.XLOOKUP(A31,'Player List'!$A$2:$A$177,'Player List'!$B$2:$C$177)} | C31: Hooker | D31: =_xlfn.XLOOKUP(B31,$B$2:$B$7,$C$2:$C$7) | E31: 19 | F31: 2 | I31: 19 | T31: 5.8
A32: K. Owens | B32: {=_xlfn.XLOOKUP(A32,'Player List'!$A$2:$A$177,'Player List'!$B$2:$C$177)} | C32: Hooker | D32: =_xlfn.XLOOKUP(B32,$B$2:$B$7,$C$2:$C$7) | E32: 61 | F32: 12 | G32: 3 | I32: 38 | T32: 40.6
A33: M. Hansen | B33: {=_xlfn.XLOOKUP(A33,'Player List'!$A$2:$A$177,'Player List'!$B$2:$C$177)} | C33: Back Three | D33: =_xlfn.XLOOKUP(B33,$B$2:$B$7,$C$2:$C$7) | E33: 80 | F33: 5 | G33: 2 | H33: 1 | I33: 34 | T33: 40.8
A34: H. Keenan | B34: {=_xlfn.XLOOKUP(A34,'Player List'!$A$2:$A$177,'Player List'!$B$2:$C$177)} | C34: Back Three | D34: =_xlfn.XLOOKUP(B34,$B$2:$B$7,$C$2:$C$7) | E34: 80 | I34: 86 | T34: 40.2 | U34: 1
A35: B. Aki | B35: {=_xlfn.XLOOKUP(A35,'Player List'!$A$2:$A$177,'Player List'!$B$2:$C$177)} | C35: Centre | D35: =_xlfn.XLOOKUP(B35,$B$2:$B$7,$C$2:$C$7) | E35: 80 | F35: 4 | H35: 1 | I35: 112 | L35: 1 | M35: 1 | T35: 63.4
A36: S. McCloskey | B36: {=_xlfn.XLOOKUP(A35,'Player List'!$A$2:$A$177,'Player List'!$B$2:$C$177)} | C36: Centre | D36: =_xlfn.XLOOKUP(B36,$B$2:$B$7,$C$2:$C$7) | E36: 20 | F36: 2 | I36: 13 | L36: 1 | T36: 13.6
A37: G. Ringrose | B37: {=_xlfn.XLOOKUP(A36,'Player List'!$A$2:$A$177,'Player List'!$B$2:$C$177)} | C37: Centre | D37: =_xlfn.XLOOKUP(B37,$B$2:$B$7,$C$2:$C$7) | E37: 60 | F37: 7 | I37: 66 | T37: 26.2
A38: R. Byrne | B38: {=_xlfn.XLOOKUP(A37,'Player List'!$A$2:$A$177,'Player List'!$B$2:$C$177)} | C38: Centre | D38: =_xlfn.XLOOKUP(B38,$B$2:$B$7,$C$2:$C$7) | E38: 80 | F38: 10 | I38: 49 | T38: 27.8
A39: J. Sexton | B39: {=_xlfn.XLOOKUP(A38,'Player List'!$A$2:$A$177,'Player List'!$B$2:$C$177)} | C39: Fly Half | D39: =_xlfn.XLOOKUP(B39,$B$2:$B$7,$C$2:$C$7) | E39: 12 | I39: 11 | O39: 1 | T39: 5.4
A40: C. Casey | B40: {=_xlfn.XLOOKUP(A39,'Player List'!$A$2:$A$177,'Player List'!$B$2:$C$177)} | C40: Fly Half | D40: =_xlfn.XLOOKUP(B40,$B$2:$B$7,$C$2:$C$7) | E40: 68 | F40: 7 | I40: 30 | L40: 1 | O40: 3 | P40: 2 | T40: 42.8
A41: C. Murray | B41: {=_xlfn.XLOOKUP(A40,'Player List'!$A$2:$A$177,'Player List'!$B$2:$C$177)} | C41: Scrum Half | D41: =_xlfn.XLOOKUP(B41,$B$2:$B$7,$C$2:$C$7) | E41: 16 | F41: 1 | I41: 1 | N41: 1 | T41: 9.8
A42: J. Conan | B42: {=_xlfn.XLOOKUP(A41,'Player List'!$A$2:$A$177,'Player List'!$B$2:$C$177)} | C42: Scrum Half | D42: =_xlfn.XLOOKUP(B42,$B$2:$B$7,$C$2:$C$7) | E42: 64 | F42: 1 | G42: 1 | H42: 1 | I42: 12 | N42: 1 | T42: 30.8
...

Sheet Round 2 Data
B2: Scotland | C2: Win | E2: Ireland | F2: 32 | G2: 19 | H2: France
B3: Wales | C3: Loss | E3: Scotland | F3: 35 | G3: 7 | H3: Wales
B4: Ireland | C4: Win | E4: England | F4: 31 | G4: 14 | H4: Italy
B5: England | C5: Win
B6: France | C6: Loss
B7: Italy | C7: Loss
A9: Name | B9: Nation | C9: Position | D9: Win/Loss | E9: Time Played | F9: Tackles | G9: Dominant Tackles | H9: Line Breaks | I9: Metres Carried | J9: 50-22 | K9: Lineout Steal | L9: Breakdown Steal | M9: Try | N9: Assists | O9: Conversion | P9: Penalty | Q9: Drop Goal | R9: Yellow Card | S9: Red Card | T9: Game Total | U9: MoM | V9: Total Points
A10: M. Hansen | B10: {=_xlfn.XLOOKUP(A10,'Player List'!$A$2:$A$177,'Player List'!$B$2:$C$177)} | C10: Back Three | D10: =_xlfn.XLOOKUP(B10,$B$2:$B$7,$C$2:$C$7) | E10: 80 | F10: 5 | I10: 63 | T10: 25.6
A11: H. Keenan | B11: {=_xlfn.XLOOKUP(A11,'Player List'!$A$2:$A$177,'Player List'!$B$2:$C$177)} | C11: Back Three | D11: =_xlfn.XLOOKUP(B11,$B$2:$B$7,$C$2:$C$7) | E11: 80 | F11: 3 | G11: 1 | H11: 2 | I11: 205 | J11: 1 | M11: 1 | T11: 98
A12: J. Lowe | B12: {=_xlfn.XLOOKUP(A12,'Player List'!$A$2:$A$177,'Player List'!$B$2:$C$177)} | C12: Back Three | D12: =_xlfn.XLOOKUP(B12,$B$2:$B$7,$C$2:$C$7) | E12: 80 | F12: 4 | H12: 1 | I12: 94 | M12: 1 | T12: 52.8
A13: B. Aki | B13: {=_xlfn.XLOOKUP(A13,'Player List'!$A$2:$A$177,'Player List'!$B$2:$C$177)} | C13: Centre | D13: =_xlfn.XLOOKUP(B13,$B$2:$B$7,$C$2:$C$7) | E13: 14 | F13: 3 | I13: 25 | T13: 9.4
A14: S. McCloskey | B14: {=_xlfn.XLOOKUP(A14,'Player List'!$A$2:$A$177,'Player List'!$B$2:$C$177)} | C14: Centre | D14: =_xlfn.XLOOKUP(B14,$B$2:$B$7,$C$2:$C$7) | E14: 66 | F14: 3 | I14: 69 | L14: 1 | T14: 30.4
A15: G. Ringrose | B15: {=_xlfn.XLOOKUP(A15,'Player List'!$A$2:$A$177,'Player List'!$B$2:$C$177)} | C15: Centre | D15: =_xlfn.XLOOKUP(B15,$B$2:$B$7,$C$2:$C$7) | E15: 80 | F15: 9 | G15: 1 | H15: 1 | I15: 64 | M15: 1 | N15: 1 | T15: 65.8
A16: R. Byrne | B16: {=_xlfn.XLOOKUP(A16,'Player List'!$A$2:$A$177,'Player List'!$B$2:$C$177)} | C16: Fly Half | D16: =_xlfn.XLOOKUP(B16,$B$2:$B$7,$C$2:$C$7) | E16: 32 | F16: 3 | I16: 10 | O16: 1 | P16: 1 | T16: 15.2
A17: J. Sexton | B17: {=_xlfn.XLOOKUP(A17,'Player List'!$A$2:$A$177,'Player List'!$B$2:$C$177)} | C17: Fly Half | D17: =_xlfn.XLOOKUP(B17,$B$2:$B$7,$C$2:$C$7) | E17: 48 | F17: 3 | H17: 2 | I17: 80 | O17: 2 | P17: 1 | T17: 46.8
A18: C. Casey | B18: {=_xlfn.XLOOKUP(A18,'Player List'!$A$2:$A$177,'Player List'!$B$2:$C$177)} | C18: Scrum Half | D18: =_xlfn.XLOOKUP(B18,$B$2:$B$7,$C$2:$C$7) | E18: 24 | F18: 1 | I18: 14 | T18: 6.2
A19: C. Murray | B19: {=_xlfn.XLOOKUP(A19,'Player List'!$A$2:$A$177,'Player List'!$B$2:$C$177)} | C19: Scrum Half | D19: =_xlfn.XLOOKUP(B19,$B$2:$B$7,$C$2:$C$7) | E19: 56 | F19: 3 | I19: 11 | T19: 10.8
A20: J. Conan | B20: {=_xlfn.XLOOKUP(A20,'Player List'!$A$2:$A$177,'Player List'!$B$2:$C$177)} | C20: Back Row | D20: =_xlfn.XLOOKUP(B20,$B$2:$B$7,$C$2:$C$7) | E20: 24 | F20: 2 | I20: 22 | T20: 8.8
A21: C. Doris | B21: {=_xlfn.XLOOKUP(A21,'Player List'!$A$2:$A$177,'Player List'!$B$2:$C$177)} | C21: Back Row | D21: =_xlfn.XLOOKUP(B21,$B$2:$B$7,$C$2:$C$7) | E21: 80 | F21: 6 | I21: 117 | L21: 1 | N21: 1 | T21: 66.4 | U21: 1
A22: P. O'Mahony | B22: {=_xlfn.XLOOKUP(A22,'Player List'!$A$2:$A$177,'Player List'!$B$2:$C$177)} | C22: Back Row | D22: =_xlfn.XLOOKUP(B22,$B$2:$B$7,$C$2:$C$7) | E22: 56 | F22: 7 | I22: 15 | T22: 15.6
A23: J. van der Flier | B23: {=_xlfn.XLOOKUP(A23,'Player List'!$A$2:$A$177,'Player List'!$B$2:$C$177)} | C23: Back Row | D23: =_xlfn.XLOOKUP(B23,$B$2:$B$7,$C$2:$C$7) | E23: 80 | F23: 12 | G23: 1 | I23: 51 | T23: 37.2
A24: T. Beirne | B24: {=_xlfn.XLOOKUP(A24,'Player List'!$A$2:$A$177,'Player List'!$B$2:$C$177)} | C24: Second Row | D24: =_xlfn.XLOOKUP(B24,$B$2:$B$7,$C$2:$C$7) | E24: 45 | F24: 10 | G24: 2 | H24: 1 | I24: 33 | L24: 1 | T24: 49.1
A25: I. Henderson | B25: {=_xlfn.XLOOKUP(A25,'Player List'!$A$2:$A$177,'Player List'!$B$2:$C$177)} | C25: Second Row | D25: =_xlfn.XLOOKUP(B25,$B$2:$B$7,$C$2:$C$7) | E25: 35 | F25: 4 | I25: 20 | T25: 11.5
A26: J. Ryan | B26: {=_xlfn.XLOOKUP(A26,'Player List'!$A$2:$A$177,'Player List'!$B$2:$C$177)} | C26: Second Row | D26: =_xlfn.XLOOKUP(B26,$B$2:$B$7,$C$2:$C$7) | E26: 80 | F26: 15 | G26: 1 | I26: 52 | T26: 40.4
A27: F. Bealham | B27: {=_xlfn.XLOOKUP(A27,'Player List'!$A$2:$A$177,'Player List'!$B$2:$C$177)} | C27: Prop | D27: =_xlfn.XLOOKUP(B27,$B$2:$B$7,$C$2:$C$7) | E27: 61 | F27: 12 | G27: 1 | I27: 11 | N27: 1 | T27: 34.3
A28: D. Kilcoyne | B28: {=_xlfn.XLOOKUP(A28,'Player List'!$A$2:$A$177,'Player List'!$B$2:$C$177)} | C28: Prop | D28: =_xlfn.XLOOKUP(B28,$B$2:$B$7,$C$2:$C$7) | E28: 11 | F28: 3 | I28: 9 | T28: 5.9
A29: T. O'Toole | B29: {=_xlfn.XLOOKUP(A29,'Player List'!$A$2:$A$177,'Player List'!$B$2:$C$177)} | C29: Prop | D29: =_xlfn.XLOOKUP(B29,$B$2:$B$7,$C$2:$C$7) | E29: 19 | I29: 52 | T29: 12.3
A30: A. Porter | B30: {=_xlfn.XLOOKUP(A30,'Player List'!$A$2:$A$177,'Player List'!$B$2:$C$177)} | C30: Prop | D30: =_xlfn.XLOOKUP(B30,$B$2:$B$7,$C$2:$C$7) | E30: 69 | F30: 6 | I30: 17 | M30: 1 | T30: 31.3
A31: R. Herring | B31: {=_xlfn.XLOOKUP(A31,'Player List'!$A$2:$A$177,'Player List'!$B$2:$C$177)} | C31: Hooker | D31: =_xlfn.XLOOKUP(B31,$B$2:$B$7,$C$2:$C$7) | E31: 25 | F31: 6 | I31: 7 | T31: 9.9
A32: R. Kelleher | B32: {=_xlfn.XLOOKUP(A32,'Player List'!$A$2:$A$177,'Player List'!$B$2:$C$177)} | C32: Hooker | D32: =_xlfn.XLOOKUP(B32,$B$2:$B$7,$C$2:$C$7) | E32: 55 | F32: 9 | G32: 2 | I32: 38 | T32: 36.1
A33: D. Penaud | B33: {=_xlfn.XLOOKUP(A33,'Player List'!$A$2:$A$177,'Player List'!$B$2:$C$177)} | C33: Back Three | D33: =_xlfn.XLOOKUP(B33,$B$2:$B$7,$C$2:$C$7) | E33: 80 | F33: 4 | H33: 1 | I33: 134 | M33: 1 | T33: 52.8
A34: T. Ramos | B34: {=_xlfn.XLOOKUP(A34,'Player List'!$A$2:$A$177,'Player List'!$B$2:$C$177)} | C34: Back Three | D34: =_xlfn.XLOOKUP(B34,$B$2:$B$7,$C$2:$C$7) | E34: 61 | F34: 3 | I34: 90 | O34: 1 | P34: 3 | Q34: 1 | T34: 45
A35: E. Dumortier | B35: {=_xlfn.XLOOKUP(A35,'Player List'!$A$2:$A$177,'Player List'!$B$2:$C$177)} | C35: Centre | D35: =_xlfn.XLOOKUP(B35,$B$2:$B$7,$C$2:$C$7) | E35: 68 | F35: 2 | H35: 2 | I35: 88 | T35: 33.6
A36: G. Fickou | B36: {=_xlfn.XLOOKUP(A36,'Player List'!$A$2:$A$177,'Player List'!$B$2:$C$177)} | C36: Centre | D36: =_xlfn.XLOOKUP(B36,$B$2:$B$7,$C$2:$C$7) | E36: 80 | F36: 14 | I36: 83 | T36: 30.6
A37: Y. Moefana | B37: {=_xlfn.XLOOKUP(A37,'Player List'!$A$2:$A$177,'Player List'!$B$2:$C$177)} | C37: Centre | D37: =_xlfn.XLOOKUP(B37,$B$2:$B$7,$C$2:$C$7) | E37: 80 | F37: 9 | I37: 57 | T37: 20.4
A38: M. Jalibert | B38: {=_xlfn.XLOOKUP(A38,'Player List'!$A$2:$A$177,'Player List'!$B$2:$C$177)} | C38: Fly Half | D38: =_xlfn.XLOOKUP(B38,$B$2:$B$7,$C$2:$C$7) | E38: 19 | F38: 2 | I38: 19 | T38: 5.8
A39: R. Ntamack | B39: {=_xlfn.XLOOKUP(A39,'Player List'!$A$2:$A$177,'Player List'!$B$2:$C$177)} | C39: Fly Half | D39: =_xlfn.XLOOKUP(B39,$B$2:$B$7,$C$2:$C$7) | E39: 80 | F39: 12 | I39: 51 | T39: 22.2
A40: A. Dupont | B40: {=_xlfn.XLOOKUP(A40,'Player List'!$A$2:$A$177,'Player List'!$B$2:$C$177)} | C40: Scrum Half | D40: =_xlfn.XLOOKUP(B40,$B$2:$B$7,$C$2:$C$7) | E40: 80 | F40: 10 | G40: 1 | H40: 2 | I40: 90 | T40: 49
A41: G. Alldritt | B41: {=_xlfn.XLOOKUP(A41,'Player List'!$A$2:$A$177,'Player List'!$B$2:$C$177)} | C41: Back Row | D41: =_xlfn.XLOOKUP(B41,$B$2:$B$7,$C$2:$C$7) | E41: 52 | F41: 13 | I41: 17 | T41: 16.4
A42: F. Cros | B42: {=_xlfn.XLOOKUP(A42,'Player List'!$A$2:$A$177,'Player List'!$B$2:$C$177)} | C42: Back Row | D42: =_xlfn.XLOOKUP(B42,$B$2:$B$7,$C$2:$C$7) | E42: 11 | F42: 6 | T42: 6
...

Sheet Round 3 Data
B2: Scotland | C2: Loss | E2: Italy | F2: 20 | G2: 34 | H2: Ireland
B3: Wales | C3: Loss | E3: Wales | F3: 10 | G3: 20 | H3: England
B4: Ireland | C4: Win | E4: France | F4: 32 | G4: 21 | H4: Scotland
B5: England | C5: Win
B6: France | C6: Win
B7: Italy | C7: Loss
A9: Name | B9: Nation | C9: Position | D9: Win/Loss | E9: Time Played | F9: Tackles | G9: Dominant Tackles | H9: Line Breaks | I9: Metres Carried | J9: 50-22 | K9: Lineout Steal | L9: Breakdown Steal | M9: Try | N9: Assists | O9: Conversion | P9: Penalty | Q9: Drop Goal | R9: Yellow Card | S9: Red Card | T9: Game Total | U9: MoM | V9: Total Points
A10: M. Hansen | B10: {=_xlfn.XLOOKUP(A10,'Player List'!$A$2:$A$177,'Player List'!$B$2:$C$177)} | C10: Back Three | D10: =_xlfn.XLOOKUP(B10,$B$2:$B$7,$C$2:$C$7) | E10: 80 | F10: 2 | H10: 3 | I10: 75 | L10: 1 | M10: 2 | T10: 98 | U10: 1
A11: H. Keenan | B11: {=_xlfn.XLOOKUP(A11,'Player List'!$A$2:$A$177,'Player List'!$B$2:$C$177)} | C11: Back Three | D11: =_xlfn.XLOOKUP(B11,$B$2:$B$7,$C$2:$C$7) | E11: 80 | F11: 3 | G11: 1 | I11: 124 | M11: 1 | T11: 57.8
A12: J. Lowe | B12: {=_xlfn.XLOOKUP(A12,'Player List'!$A$2:$A$177,'Player List'!$B$2:$C$177)} | C12: Back Three | D12: =_xlfn.XLOOKUP(B12,$B$2:$B$7,$C$2:$C$7) | E12: 80 | F12: 1 | G12: 2 | H12: 4 | I12: 131 | N12: 2 | T12: 91.2
A13: J. O'Brien | B13: {=_xlfn.XLOOKUP(A13,'Player List'!$A$2:$A$177,'Player List'!$B$2:$C$177)} | C13: Back Three | D13: =_xlfn.XLOOKUP(B13,$B$2:$B$7,$C$2:$C$7) | E13: 8 | T13: 0.8
A14: B. Aki | B14: {=_xlfn.XLOOKUP(A14,'Player List'!$A$2:$A$177,'Player List'!$B$2:$C$177)} | C14: Centre | D14: =_xlfn.XLOOKUP(B14,$B$2:$B$7,$C$2:$C$7) | E14: 80 | F14: 7 | H14: 1 | I14: 107 | L14: 1 | M14: 1 | N14: 1 | T14: 72.4
A15: S. McCloskey | B15: {=_xlfn.XLOOKUP(A15,'Player List'!$A$2:$A$177,'Player List'!$B$2:$C$177)} | C15: Centre | D15: =_xlfn.XLOOKUP(B15,$B$2:$B$7,$C$2:$C$7) | E15: 72 | F15: 14 | I15: 69 | N15: 1 | T15: 42
A16: R. Byrne | B16: {=_xlfn.XLOOKUP(A16,'Player List'!$A$2:$A$177,'Player List'!$B$2:$C$177)} | C16: Fly Half | D16: =_xlfn.XLOOKUP(B16,$B$2:$B$7,$C$2:$C$7) | E16: 78 | F16: 4 | I16: 12 | O16: 3 | P16: 1 | T16: 25.2
A17: J. Crowley | B17: {=_xlfn.XLOOKUP(A17,'Player List'!$A$2:$A$177,'Player List'!$B$2:$C$177)} | C17: Fly Half | D17: =_xlfn.XLOOKUP(B17,$B$2:$B$7,$C$2:$C$7) | E17: 2 | F17: 2 | T17: 2.2
A18: C. Casey | B18: {=_xlfn.XLOOKUP(A18,'Player List'!$A$2:$A$177,'Player List'!$B$2:$C$177)} | C18: Scrum Half | D18: =_xlfn.XLOOKUP(B18,$B$2:$B$7,$C$2:$C$7) | E18: 65 | F18: 2 | I18: 4 | T18: 9.3
A19: C. Murray | B19: {=_xlfn.XLOOKUP(A19,'Player List'!$A$2:$A$177,'Player List'!$B$2:$C$177)} | C19: Scrum Half | D19: =_xlfn.XLOOKUP(B19,$B$2:$B$7,$C$2:$C$7) | E19: 15 | F19: 1 | I19: 6 | N19: 1 | T19: 10.7
A20: J. Conan | B20: {=_xlfn.XLOOKUP(A20,'Player List'!$A$2:$A$177,'Player List'!$B$2:$C$177)} | C20: Back Row | D20: =_xlfn.XLOOKUP(B20,$B$2:$B$7,$C$2:$C$7) | E20: 56 | F20: 4 | I20: 42 | T20: 18
A21: C. Doris | B21: {=_xlfn.XLOOKUP(A21,'Player List'!$A$2:$A$177,'Player List'!$B$2:$C$177)} | C21: Back Row | D21: =_xlfn.XLOOKUP(B21,$B$2:$B$7,$C$2:$C$7) | E21: 80 | F21: 10 | G21: 1 | I21: 43 | L21: 1 | T21: 40.6
A22: P. O'Mahony | B22: {=_xlfn.XLOOKUP(A22,'Player List'!$A$2:$A$177,'Player List'!$B$2:$C$177)} | C22: Back Row | D22: =_xlfn.XLOOKUP(B22,$B$2:$B$7,$C$2:$C$7) | E22: 24 | F22: 4 | G22: 1 | I22: 4 | T22: 14.2
A23: J. van der Flier | B23: {=_xlfn.XLOOKUP(A23,'Player List'!$A$2:$A$177,'Player List'!$B$2:$C$177)} | C23: Back Row | D23: =_xlfn.XLOOKUP(B23,$B$2:$B$7,$C$2:$C$7) | E23: 80 | F23: 12 | H23: 1 | I23: 52 | T23: 37.4
A24: R. Baird | B24: {=_xlfn.XLOOKUP(A24,'Player List'!$A$2:$A$177,'Player List'!$B$2:$C$177)} | C24: Second Row | D24: =_xlfn.XLOOKUP(B24,$B$2:$B$7,$C$2:$C$7) | E24: 28 | F24: 1 | G24: 1 | I24: 8 | K24: 1 | L24: 1 | T24: 26.4
A25: I. Henderson | B25: {=_xlfn.XLOOKUP(A25,'Player List'!$A$2:$A$177,'Player List'!$B$2:$C$177)} | C25: Second Row | D25: =_xlfn.XLOOKUP(B25,$B$2:$B$7,$C$2:$C$7) | E25: 52 | F25: 7 | I25: 13 | T25: 14.8
A26: J. Ryan | B26: {=_xlfn.XLOOKUP(A26,'Player List'!$A$2:$A$177,'Player List'!$B$2:$C$177)} | C26: Second Row | D26: =_xlfn.XLOOKUP(B26,$B$2:$B$7,$C$2:$C$7) | E26: 80 | F26: 9 | G26: 1 | I26: 53 | M26: 1 | T26: 49.6
A27: F. Bealham | B27: {=_xlfn.XLOOKUP(A27,'Player List'!$A$2:$A$177,'Player List'!$B$2:$C$177)} | C27: Prop | D27: =_xlfn.XLOOKUP(B27,$B$2:$B$7,$C$2:$C$7) | E27: 37 | F27: 2 | G27: 1 | I27: 1 | T27: 12.9
A28: D. Kilcoyne | B28: {=_xlfn.XLOOKUP(A28,'Player List'!$A$2:$A$177,'Player List'!$B$2:$C$177)} | C28: Prop | D28: =_xlfn.XLOOKUP(B28,$B$2:$B$7,$C$2:$C$7) | E28: 15 | G28: 1 | I28: 7 | T28: 9.9
A29: T. O'Toole | B29: {=_xlfn.XLOOKUP(A29,'Player List'!$A$2:$A$177,'Player List'!$B$2:$C$177)} | C29: Prop | D29: =_xlfn.XLOOKUP(B29,$B$2:$B$7,$C$2:$C$7) | E29: 43 | F29: 6 | I29: 24 | L29: 1 | T29: 22.1
A30: A. Porter | B30: {=_xlfn.XLOOKUP(A30,'Player List'!$A$2:$A$177,'Player List'!$B$2:$C$177)} | C30: Prop | D30: =_xlfn.XLOOKUP(B30,$B$2:$B$7,$C$2:$C$7) | E30: 65 | F30: 3 | I30: 10 | L30: 1 | T30: 18.5
A31: R. Kelleher | B31: {=_xlfn.XLOOKUP(A31,'Player List'!$A$2:$A$177,'Player List'!$B$2:$C$177)} | C31: Hooker | D31: =_xlfn.XLOOKUP(B31,$B$2:$B$7,$C$2:$C$7) | E31: 56 | F31: 9 | I31: 23 | L31: 1 | T31: 26.2
A32: D. Sheehan | B32: {=_xlfn.XLOOKUP(A32,'Player List'!$A$2:$A$177,'Player List'!$B$2:$C$177)} | C32: Hooker | D32: =_xlfn.XLOOKUP(B32,$B$2:$B$7,$C$2:$C$7) | E32: 24 | F32: 2 | G32: 2 | I32: 5 | T32: 19.4
A33: P. Bruno | B33: {=_xlfn.XLOOKUP(A33,'Player List'!$A$2:$A$177,'Player List'!$B$2:$C$177)} | C33: Back Three | D33: =_xlfn.XLOOKUP(B33,$B$2:$B$7,$C$2:$C$7) | E33: 80 | F33: 3 | H33: 1 | I33: 176 | M33: 1 | T33: 60.2
A34: A. Capuozzo | B34: {=_xlfn.XLOOKUP(A34,'Player List'!$A$2:$A$177,'Player List'!$B$2:$C$177)} | C34: Back Three | D34: =_xlfn.XLOOKUP(B34,$B$2:$B$7,$C$2:$C$7) | E34: 80 | F34: 3 | G34: 1 | H34: 1 | I34: 60 | L34: 1 | T34: 36
A35: A. Fusco | B35: {=_xlfn.XLOOKUP(A35,'Player List'!$A$2:$A$177,'Player List'!$B$2:$C$177)} | C35: Back Three | D35: =_xlfn.XLOOKUP(B35,$B$2:$B$7,$C$2:$C$7) | E35: 13 | T35: 0
A36: T. Menoncello | B36: {=_xlfn.XLOOKUP(A36,'Player List'!$A$2:$A$177,'Player List'!$B$2:$C$177)} | C36: Back Three | D36: =_xlfn.XLOOKUP(B36,$B$2:$B$7,$C$2:$C$7) | E36: 78 | F36: 12 | H36: 1 | I36: 72 | T36: 33.4
A37: E. Padovani | B37: {=_xlfn.XLOOKUP(A37,'Player List'!$A$2:$A$177,'Player List'!$B$2:$C$177)} | C37: Back Three | D37: =_xlfn.XLOOKUP(B37,$B$2:$B$7,$C$2:$C$7) | E37: 80 | I37: 51 | T37: 10.2
A38: J. Brex | B38: {=_xlfn.XLOOKUP(A38,'Player List'!$A$2:$A$177,'Player List'!$B$2:$C$177)} | C38: Centre | D38: =_xlfn.XLOOKUP(B38,$B$2:$B$7,$C$2:$C$7) | E38: 80 | F38: 8 | G38: 1 | I38: 26 | T38: 20.2
A39: L. Morisi | B39: {=_xlfn.XLOOKUP(A39,'Player List'!$A$2:$A$177,'Player List'!$B$2:$C$177)} | C39: Centre | D39: =_xlfn.XLOOKUP(B39,$B$2:$B$7,$C$2:$C$7) | E39: 2 | F39: 1 | T39: 1
A40: T. Allan | B40: {=_xlfn.XLOOKUP(A40,'Player List'!$A$2:$A$177,'Player List'!$B$2:$C$177)} | C40: Fly Half | D40: =_xlfn.XLOOKUP(B40,$B$2:$B$7,$C$2:$C$7) | E40: 8 | F40: 1 | I40: 14 | T40: 3.8
A41: P. Garbisi | B41: {=_xlfn.XLOOKUP(A41,'Player List'!$A$2:$A$177,'Player List'!$B$2:$C$177)} | C41: Fly Half | D41: =_xlfn.XLOOKUP(B41,$B$2:$B$7,$C$2:$C$7) | E41: 72 | F41: 5 | I41: 42 | O41: 2 | P41: 2 | T41: 27.4
A42: S. Varney | B42: {=_xlfn.XLOOKUP(A42,'Player List'!$A$2:$A$177,'Player List'!$B$2:$C$177)} | C42: Scrum Half | D42: =_xlfn.XLOOKUP(B42,$B$2:$B$7,$C$2:$C$7) | E42: 67 | F42: 1 | G42: 1 | I42: 12 | M42: 1 | T42: 25.4
...

Sheet Round 4 Data
B2: Scotland | C2: Loss | E2: Italy | F2: 17 | G2: 29 | H2: Wales
B3: Wales | C3: Win | E3: England | F3: 53 | G3: 10 | H3: France
B4: Ireland | C4: Win | E4: Scotland | F4: 7 | G4: 22 | H4: Ireland
B5: England | C5: Loss
B6: France | C6: Win
B7: Italy | C7: Loss
A9: Name | B9: Nation | C9: Position | D9: Win/Loss | E9: Time Played | F9: Tackles | G9: Dominant Tackles | H9: Line Breaks | I9: Metres Carried | J9: 50-22 | K9: Lineout Steal | L9: Breakdown Steal | M9: Try | N9: Assists | O9: Conversion | P9: Penalty | Q9: Drop Goal | R9: Yellow Card | S9: Red Card | T9: Game Total | U9: MoM | V9: Total Points
A10: P. Bruno | B10: {=_xlfn.XLOOKUP(A10,'Player List'!$A$2:$A$177,'Player List'!$B$2:$C$177)} | C10: Back Three | D10: =_xlfn.XLOOKUP(B10,$B$2:$B$7,$C$2:$C$7) | E10: 69 | F10: 2 | I10: 29 | N10: 1 | R10: 1 | T10: 9.8
A11: A. Fusco | B11: {=_xlfn.XLOOKUP(A11,'Player List'!$A$2:$A$177,'Player List'!$B$2:$C$177)} | C11: Back Three | D11: =_xlfn.XLOOKUP(B11,$B$2:$B$7,$C$2:$C$7) | E11: 24 | H11: 1 | I11: 50 | T11: 17
A12: T. Menoncello | B12: {=_xlfn.XLOOKUP(A12,'Player List'!$A$2:$A$177,'Player List'!$B$2:$C$177)} | C12: Back Three | D12: =_xlfn.XLOOKUP(B12,$B$2:$B$7,$C$2:$C$7) | E12: 59 | F12: 7 | G12: 1 | H12: 1 | I12: 79 | T12: 36.8
A13: E. Padovani | B13: {=_xlfn.XLOOKUP(A13,'Player List'!$A$2:$A$177,'Player List'!$B$2:$C$177)} | C13: Back Three | D13: =_xlfn.XLOOKUP(B13,$B$2:$B$7,$C$2:$C$7) | E13: 80 | F13: 1 | G13: 1 | H13: 1 | I13: 51 | T13: 25.2
A14: J. Brex | B14: {=_xlfn.XLOOKUP(A14,'Player List'!$A$2:$A$177,'Player List'!$B$2:$C$177)} | C14: Centre | D14: =_xlfn.XLOOKUP(B14,$B$2:$B$7,$C$2:$C$7) | E14: 80 | F14: 2 | H14: 1 | I14: 90 | M14: 1 | T14: 42
A15: L. Morisi | B15: {=_xlfn.XLOOKUP(A15,'Player List'!$A$2:$A$177,'Player List'!$B$2:$C$177)} | C15: Centre | D15: =_xlfn.XLOOKUP(B15,$B$2:$B$7,$C$2:$C$7) | E15: 21 | I15: 24 | T15: 4.8
A16: T. Allan | B16: {=_xlfn.XLOOKUP(A16,'Player List'!$A$2:$A$177,'Player List'!$B$2:$C$177)} | C16: Fly Half | D16: =_xlfn.XLOOKUP(B16,$B$2:$B$7,$C$2:$C$7) | E16: 80 | H16: 3 | I16: 78 | N16: 1 | O16: 2 | P16: 1 | T16: 52.6
A17: P. Garbisi | B17: {=_xlfn.XLOOKUP(A17,'Player List'!$A$2:$A$177,'Player List'!$B$2:$C$177)} | C17: Fly Half | D17: =_xlfn.XLOOKUP(B17,$B$2:$B$7,$C$2:$C$7) | E17: 80 | F17: 6 | H17: 1 | I17: 37 | T17: 20.4
A18: S. Varney | B18: {=_xlfn.XLOOKUP(A18,'Player List'!$A$2:$A$177,'Player List'!$B$2:$C$177)} | C18: Scrum Half | D18: =_xlfn.XLOOKUP(B18,$B$2:$B$7,$C$2:$C$7) | E18: 56 | F18: 3 | I18: 38 | T18: 10.6
A19: E. Iachizzi | B19: {=_xlfn.XLOOKUP(A19,'Player List'!$A$2:$A$177,'Player List'!$B$2:$C$177)} | C19: Back Row | D19: =_xlfn.XLOOKUP(B19,$B$2:$B$7,$C$2:$C$7) | E19: 20 | F19: 1 | H19: 1 | I19: 28 | L19: 1 | T19: 20.6
A20: M. Lamaro | B20: {=_xlfn.XLOOKUP(A20,'Player List'!$A$2:$A$177,'Player List'!$B$2:$C$177)} | C20: Back Row | D20: =_xlfn.XLOOKUP(B20,$B$2:$B$7,$C$2:$C$7) | E20: 77 | F20: 7 | I20: 24 | T20: 11.8
A21: S. Negri | B21: {=_xlfn.XLOOKUP(A21,'Player List'!$A$2:$A$177,'Player List'!$B$2:$C$177)} | C21: Back Row | D21: =_xlfn.XLOOKUP(B21,$B$2:$B$7,$C$2:$C$7) | E21: 52 | F21: 5 | H21: 1 | I21: 50 | M21: 1 | T21: 37
A22: G. Pettinelli | B22: {=_xlfn.XLOOKUP(A22,'Player List'!$A$2:$A$177,'Player List'!$B$2:$C$177)} | C22: Back Row | D22: =_xlfn.XLOOKUP(B22,$B$2:$B$7,$C$2:$C$7) | E22: 3 | T22: 0
A23: N. Cannone | B23: {=_xlfn.XLOOKUP(A23,'Player List'!$A$2:$A$177,'Player List'!$B$2:$C$177)} | C23: Second Row | D23: =_xlfn.XLOOKUP(B23,$B$2:$B$7,$C$2:$C$7) | E23: 60 | F23: 3 | I23: 16 | T23: 6.2
A24: L. Cannone | B24: {=_xlfn.XLOOKUP(A24,'Player List'!$A$2:$A$177,'Player List'!$B$2:$C$177)} | C24: Second Row | D24: =_xlfn.XLOOKUP(B24,$B$2:$B$7,$C$2:$C$7) | E24: 71 | F24: 7 | G24: 1 | I24: 51 | R24: 1 | T24: 19.2
A25: F. Ruzza | B25: {=_xlfn.XLOOKUP(A25,'Player List'!$A$2:$A$177,'Player List'!$B$2:$C$177)} | C25: Second Row | D25: =_xlfn.XLOOKUP(B25,$B$2:$B$7,$C$2:$C$7) | E25: 80 | F25: 3 | I25: 35 | T25: 10
A26: M. Zuliani | B26: {=_xlfn.XLOOKUP(A26,'Player List'!$A$2:$A$177,'Player List'!$B$2:$C$177)} | C26: Second Row | D26: =_xlfn.XLOOKUP(B26,$B$2:$B$7,$C$2:$C$7) | E26: 28 | F26: 1 | H26: 1 | I26: 36 | L26: 1 | T26: 22.2
A27: S. Ferrari | B27: {=_xlfn.XLOOKUP(A27,'Player List'!$A$2:$A$177,'Player List'!$B$2:$C$177)} | C27: Prop | D27: =_xlfn.XLOOKUP(B27,$B$2:$B$7,$C$2:$C$7) | E27: 42 | F27: 4 | G27: 1 | T27: 11
A28: D. Fischetti | B28: {=_xlfn.XLOOKUP(A28,'Player List'!$A$2:$A$177,'Player List'!$B$2:$C$177)} | C28: Prop | D28: =_xlfn.XLOOKUP(B28,$B$2:$B$7,$C$2:$C$7) | E28: 62 | F28: 5 | I28: 39 | T28: 12.8
A29: M. Riccioni | B29: {=_xlfn.XLOOKUP(A29,'Player List'!$A$2:$A$177,'Player List'!$B$2:$C$177)} | C29: Prop | D29: =_xlfn.XLOOKUP(B29,$B$2:$B$7,$C$2:$C$7) | E29: 38 | F29: 2 | I29: 14 | T29: 4.8
A30: F. Zani | B30: {=_xlfn.XLOOKUP(A30,'Player List'!$A$2:$A$177,'Player List'!$B$2:$C$177)} | C30: Prop | D30: =_xlfn.XLOOKUP(B30,$B$2:$B$7,$C$2:$C$7) | E30: 18 | T30: 0
A31: L. Bigi | B31: {=_xlfn.XLOOKUP(A31,'Player List'!$A$2:$A$177,'Player List'!$B$2:$C$177)} | C31: Hooker | D31: =_xlfn.XLOOKUP(B31,$B$2:$B$7,$C$2:$C$7) | E31: 28 | F31: 3 | T31: 3
A32: G. Nicotera | B32: {=_xlfn.XLOOKUP(A32,'Player List'!$A$2:$A$177,'Player List'!$B$2:$C$177)} | C32: Hooker | D32: =_xlfn.XLOOKUP(B32,$B$2:$B$7,$C$2:$C$7) | E32: 52 | F32: 11 | I32: 17 | L32: 1 | T32: 21.4
A33: J. Adams | B33: {=_xlfn.XLOOKUP(A33,'Player List'!$A$2:$A$177,'Player List'!$B$2:$C$177)} | C33: Back Three | D33: =_xlfn.XLOOKUP(B33,$B$2:$B$7,$C$2:$C$7) | E33: 51 | F33: 1 | G33: 1 | H33: 1 | I33: 31 | T33: 26.3
A34: R. Dyer | B34: {=_xlfn.XLOOKUP(A34,'Player List'!$A$2:$A$177,'Player List'!$B$2:$C$177)} | C34: Back Three | D34: =_xlfn.XLOOKUP(B34,$B$2:$B$7,$C$2:$C$7) | E34: 80 | F34: 4 | G34: 1 | H34: 1 | I34: 19 | M34: 1 | T34: 44.8
A35: L. Rees-Zammit | B35: {=_xlfn.XLOOKUP(A35,'Player List'!$A$2:$A$177,'Player List'!$B$2:$C$177)} | C35: Back Three | D35: =_xlfn.XLOOKUP(B35,$B$2:$B$7,$C$2:$C$7) | E35: 29 | F35: 3 | I35: 46 | T35: 15.1
A36: L. Williams | B36: {=_xlfn.XLOOKUP(A36,'Player List'!$A$2:$A$177,'Player List'!$B$2:$C$177)} | C36: Back Three | D36: =_xlfn.XLOOKUP(B36,$B$2:$B$7,$C$2:$C$7) | E36: 62 | F36: 1 | H36: 1 | I36: 87 | L36: 1 | M36: 1 | T36: 53.6
A37: M. Grady | B37: {=_xlfn.XLOOKUP(A37,'Player List'!$A$2:$A$177,'Player List'!$B$2:$C$177)} | C37: Centre | D37: =_xlfn.XLOOKUP(B37,$B$2:$B$7,$C$2:$C$7) | E37: 80 | F37: 5 | I37: 26 | T37: 18.2
A38: J. Hawkins | B38: {=_xlfn.XLOOKUP(A38,'Player List'!$A$2:$A$177,'Player List'!$B$2:$C$177)} | C38: Centre | D38: =_xlfn.XLOOKUP(B38,$B$2:$B$7,$C$2:$C$7) | E38: 80 | F38: 3 | G38: 1 | I38: 97 | T38: 37.4
A39: G. North | B39: {=_xlfn.XLOOKUP(A39,'Player List'!$A$2:$A$177,'Player List'!$B$2:$C$177)} | C39: Centre | D39: =_xlfn.XLOOKUP(B39,$B$2:$B$7,$C$2:$C$7) | E39: 18 | F39: 1 | T39: 2.8
A40: O. Williams | B40: {=_xlfn.XLOOKUP(A40,'Player List'!$A$2:$A$177,'Player List'!$B$2:$C$177)} | C40: Fly Half | D40: =_xlfn.XLOOKUP(B40,$B$2:$B$7,$C$2:$C$7) | E40: 80 | F40: 8 | I40: 19 | O40: 2 | P40: 1 | T40: 28.8
A41: R. Webb | B41: {=_xlfn.XLOOKUP(A41,'Player List'!$A$2:$A$177,'Player List'!$B$2:$C$177)} | C41: Scrum Half | D41: =_xlfn.XLOOKUP(B41,$B$2:$B$7,$C$2:$C$7) | E41: 54 | F41: 5 | G41: 1 | H41: 1 | I41: 28 | J41: 1 | N41: 2 | T41: 69 | U41: 1
A42: T. Williams | B42: {=_xlfn.XLOOKUP(A42,'Player List'!$A$2:$A$177,'Player List'!$B$2:$C$177)} | C42: Scrum Half | D42: =_xlfn.XLOOKUP(B42,$B$2:$B$7,$C$2:$C$7) | E42: 26 | F42: 2 | T42: 4.6
...

Sheet Summary Data
E2: Average
A3: Name | B3: Nation | C3: Position | D3: Games Played | E3: Time Played | F3: Tackles | G3: Dominant Tackles | H3: Line Breaks | I3: Metres Carried | J3: 50-22 | K3: Lineout Steal | L3: Breakdown Steal | M3: Try | N3: Assists | O3: Conversion | P3: Penalty | Q3: Drop Goal | R3: Yellow Card | S3: Red Card | T3: Total MoM
A4: J. Adams | B4: Wales | C4: Back Three | D4: 4 | E4: 61 | F4: 3.75 | G4: 1.25 | H4: 0.25 | I4: 26.25 | J4: 0 | K4: 0 | L4: 0.25 | M4: 0 | N4: 0 | O4: 0 | P4: 0 | Q4: 0 | R4: 0 | S4: 0 | T4: 0
A5: A. Cuthbert | B5: Wales | C5: Back Three | D5: 2 | E5: 20 | F5: 1 | G5: 0 | H5: 0 | I5: 37.5 | J5: 0 | K5: 0 | L5: 0 | M5: 0 | N5: 0 | O5: 0 | P5: 0 | Q5: 0 | R5: 0 | S5: 0 | T5: 0
A6: R. Dyer | B6: Wales | C6: Back Three | D6: 3 | E6: 76 | F6: 4.3333 | G6: 0.3333 | H6: 1.3333 | I6: 72 | J6: 0 | K6: 0 | L6: 0 | M6: 0.3333 | N6: 0 | O6: 0 | P6: 0 | Q6: 0 | R6: 0 | S6: 0 | T6: 0
A7: L. Williams | B7: Wales | C7: Back Three | D7: 3 | E7: 67 | F7: 4 | G7: 0 | H7: 1 | I7: 79.6667 | J7: 0 | K7: 0 | L7: 0.6667 | M7: 0.6667 | N7: 0 | O7: 0 | P7: 0 | Q7: 0 | R7: 0.6667 | S7: 0 | T7: 0
A8: J. Hawkins | B8: Wales | C8: Centre | D8: 4 | E8: 80 | F8: 5.5 | G8: 0.5 | H8: 0.25 | I8: 69.25 | J8: 0 | K8: 0 | L8: 0 | M8: 0 | N8: 0 | O8: 0 | P8: 0 | Q8: 0 | R8: 0 | S8: 0 | T8: 0
A9: G. North | B9: Wales | C9: Centre | D9: 3 | E9: 57 | F9: 2.3333 | G9: 0.3333 | H9: 0 | I9: 36.3333 | J9: 0 | K9: 0 | L9: 0 | M9: 0 | N9: 0 | O9: 0 | P9: 0 | Q9: 0 | R9: 0 | S9: 0 | T9: 0
A10: D. Biggar | B10: Wales | C10: Fly Half | D10: 3 | E10: 50 | F10: 6.3333 | G10: 0 | H10: 0.3333 | I10: 17 | J10: 0 | K10: 0 | L10: 0.3333 | M10: 0 | N10: 0.3333 | O10: 0.6667 | P10: 0.3333 | Q10: 0 | R10: 0 | S10: 0 | T10: 0
A11: O. Williams | B11: Wales | C11: Fly Half | D11: 3 | E11: 49 | F11: 5 | G11: 0 | H11: 0 | I11: 15.6667 | J11: 0 | K11: 0 | L11: 0 | M11: 0 | N11: 0 | O11: 0.6667 | P11: 0.3333 | Q11: 0 | R11: 0 | S11: 0 | T11: 0
A12: R. Webb | B12: Wales | C12: Scrum Half | D12: 3 | E12: 31.3333 | F12: 3 | G12: 0.6667 | H12: 0.3333 | I12: 9.6667 | J12: 0.3333 | K12: 0 | L12: 0 | M12: 0 | N12: 0.6667 | O12: 0 | P12: 0 | Q12: 0 | R12: 0.3333 | S12: 0 | T12: 1
A13: T. Williams | B13: Wales | C13: Scrum Half | D13: 4 | E13: 53.75 | F13: 3.5 | G13: 0.25 | H13: 0 | I13: 14.5 | J13: 0 | K13: 0 | L13: 0 | M13: 0 | N13: 0 | O13: 0 | P13: 0 | Q13: 0 | R13: 0 | S13: 0 | T13: 0
A14: T. Faletau | B14: Wales | C14: Back Row | D14: 4 | E14: 67 | F14: 12.75 | G14: 0.25 | H14: 0 | I14: 45.75 | J14: 0 | K14: 0 | L14: 0.5 | M14: 0.25 | N14: 0 | O14: 0 | P14: 0 | Q14: 0 | R14: 0 | S14: 0 | T14: 0
A15: J. Morgan | B15: Wales | C15: Back Row | D15: 3 | E15: 64 | F15: 13 | G15: 1 | H15: 0 | I15: 31.3333 | J15: 0 | K15: 0 | L15: 1 | M15: 0 | N15: 0 | O15: 0 | P15: 0 | Q15: 0 | R15: 0 | S15: 0 | T15: 0
... A179: C. Healy | B179: Ireland | C179: Prop | D179: 1 | E179: 32 | F179: 1 | G179: 0 | H179: 0 | I179: 15 | J179: 0 | K179: 0 | L179: 0 | M179: 0 | N179: 0 | O179: 0 | P179: 0 | Q179: 0 | R179: 0 | S179: 0 | T179: 0

Sheet Points ----->

Sheet Player List
A2: J. Adams | B2: Wales | C2: Back Three
A3: A. Cuthbert | B3: Wales | C3: Back Three
A4: R. Dyer | B4: Wales | C4: Back Three
A5: L. Williams | B5: Wales | C5: Back Three
A6: J. Hawkins | B6: Wales | C6: Centre
A7: G. North | B7: Wales | C7: Centre
A8: D. Biggar | B8: Wales | C8: Fly Half
A9: O. Williams | B9: Wales | C9: Fly Half
A10: R. Webb | B10: Wales | C10: Scrum Half
A11: T. Williams | B11: Wales | C11: Scrum Half
A12: T. Faletau | B12: Wales | C12: Back Row
A13: J. Morgan | B13: Wales | C13: Back Row
... A177: C. Healy | B177: Ireland | C177: Prop

Sheet Round 1 Points
K1: Win | L1: Tackles | M1: Dominant Tackles | N1: Line Breaks | O1: Metres Carried | P1: 50-22 | Q1: Lineout Steal | R1: Breakdown Steal | S1: Try | T1: Assists | U1: Conversion | V1: Penalty | W1: Drop Goal | X1: Yellow Card | Y1: Red Card | Z1: MOM
B2: Scotland | C2: Win | E2: Wales | F2: 10 | G2: 34 | H2: Ireland | J2: Points | K2: 8 | L2: 1 | M2: 7 | N2: 7 | O2: 0.2 | P2: 10 | Q2: 7 | R2: 7 | S2: 15 | T2: 7 | U2: 2 | V2: 5 | W2: 7 | X2: -5 | Y2: -10 | Z2: 15
B3: Wales | C3: Loss | E3: England | F3: 23 | G3: 29 | H3: Scotland
B4: Ireland | C4: Win | E4: Italy | F4: 24 | G4: 29 | H4: France
B5: England | C5: Loss
B6: France | C6: Win
B7: Italy | C7: Loss
A9: Name | B9: Nation | C9: Position | D9: Time Played | F9: Tackles | G9: Dominant Tackles | H9: Line Breaks | I9: Metres Carried | J9: 50-22 | K9: Lineout Steal | L9: Breakdown Steal | M9: Try | N9: Assists | O9: Conversion | P9: Penalty | Q9: Drop Goal | R9: Yellow Card | S9: Red Card | T9: Game Total | U9: MoM | V9: Win Points | W9: Total Points
A10: J. Adams | B10: {=_xlfn.XLOOKUP(A10,'Player List'!$A$2:$A$177,'Player List'!$B$2:$C$177)} | C10: Back Three | D10: 80 | F10: 3 | G10: 21 | H10: 0 | I10: 7.2 | J10: 0 | K10: 0 | L10: 0 | M10: 0 | N10: 0 | O10: 0 | P10: 0 | Q10: 0 | R10: 0 | S10: 0 | T10: 31.2 | U10: 0 | V10: 0 | W10: 31.2
A11: A. Cuthbert | B11: {=_xlfn.XLOOKUP(A11,'Player List'!$A$2:$A$177,'Player List'!$B$2:$C$177)} | C11: Back Three | D11: 12 | F11: 1 | G11: 0 | H11: 0 | I11: 5.6 | J11: 0 | K11: 0 | L11: 0 | M11: 0 | N11: 0 | O11: 0 | P11: 0 | Q11: 0 | R11: 0 | S11: 0 | T11: 6.6 | U11: 0 | V11: 0 | W11: 6.6
A12: R. Dyer | B12: {=_xlfn.XLOOKUP(A12,'Player List'!$A$2:$A$177,'Player List'!$B$2:$C$177)} | C12: Back Three | D12: 68 | F12: 4 | G12: 0 | H12: 14 | I12: 21.4 | J12: 0 | K12: 0 | L12: 0 | M12: 0 | N12: 0 | O12: 0 | P12: 0 | Q12: 0 | R12: 0 | S12: 0 | T12: 39.4 | U12: 0 | V12: 0 | W12: 39.4
A13: L. Williams | B13: {=_xlfn.XLOOKUP(A13,'Player List'!$A$2:$A$177,'Player List'!$B$2:$C$177)} | C13: Back Three | D13: 70 | F13: 2 | G13: 0 | H13: 14 | I13: 21.6 | J13: 0 | K13: 0 | L13: 7 | M13: 15 | N13: 0 | O13: 0 | P13: 0 | Q13: 0 | R13: -5 | S13: 0 | T13: 54.6 | U13: 0 | V13: 0 | W13: 54.6
A14: J. Hawkins | B14: {=_xlfn.XLOOKUP(A14,'Player List'!$A$2:$A$177,'Player List'!$B$2:$C$177)} | C14: Centre | D14: 80 | F14: 6 | G14: 7 | H14: 7 | I14: 15 | J14: 0 | K14: 0 | L14: 0 | M14: 0 | N14: 0 | O14: 0 | P14: 0 | Q14: 0 | R14: 0 | S14: 0 | T14: 35 | U14: 0 | V14: 0 | W14: 35
A15: G. North | B15: {=_xlfn.XLOOKUP(A15,'Player List'!$A$2:$A$177,'Player List'!$B$2:$C$177)} | C15: Centre | D15: 80 | F15: 4 | G15: 0 | H15: 0 | I15: 11.6 | J15: 0 | K15: 0 | L15: 0 | M15: 0 | N15: 0 | O15: 0 | P15: 0 | Q15: 0 | R15: 0 | S15: 0 | T15: 15.6 | U15: 0 | V15: 0 | W15: 15.6
A16: D. Biggar | B16: {=_xlfn.XLOOKUP(A16,'Player List'!$A$2:$A$177,'Player List'!$B$2:$C$177)} | C16: Fly Half | D16: 67 | F16: 9 | G16: 0 | H16: 7 | I16: 7 | J16: 0 | K16: 0 | L16: 0 | M16: 0 | N16: 7 | O16: 2 | P16: 5 | Q16: 0 | R16: 0 | S16: 0 | T16: 37 | U16: 0 | V16: 0 | W16: 37
A17: O. Williams | B17: {=_xlfn.XLOOKUP(A17,'Player List'!$A$2:$A$177,'Player List'!$B$2:$C$177)} | C17: Fly Half | D17: 13 | F17: 1 | G17: 0 | H17: 0 | I17: 0.8 | J17: 0 | K17: 0 | L17: 0 | M17: 0 | N17: 0 | O17: 0 | P17: 0 | Q17: 0 | R17: 0 | S17: 0 | T17: 1.8 | U17: 0 | V17: 0 | W17: 1.8
A18: R. Webb | B18: {=_xlfn.XLOOKUP(A18,'Player List'!$A$2:$A$177,'Player List'!$B$2:$C$177)} | C18: Scrum Half | D18: 17 | F18: 2 | G18: 7 | H18: 0 | I18: 0.2 | J18: 0 | K18: 0 | L18: 0 | M18: 0 | N18: 0 | O18: 0 | P18: 0 | Q18: 0 | R18: 0 | S18: 0 | T18: 9.2 | U18: 0 | V18: 0 | W18: 9.2
A19: T. Williams | B19: {=_xlfn.XLOOKUP(A19,'Player List'!$A$2:$A$177,'Player List'!$B$2:$C$177)} | C19: Scrum Half | D19: 63 | F19: 6 | G19: 0 | H19: 0 | I19: 3.8 | J19: 0 | K19: 0 | L19: 0 | M19: 0 | N19: 0 | O19: 0 | P19: 0 | Q19: 0 | R19: 0 | S19: 0 | T19: 9.8 | U19: 0 | V19: 0 | W19: 9.8
A20: T. Faletau | B20: {=_xlfn.XLOOKUP(A20,'Player List'!$A$2:$A$177,'Player List'!$B$2:$C$177)} | C20: Back Row | D20: 80 | F20: 20 | G20: 7 | H20: 0 | I20: 9.8 | J20: 0 | K20: 0 | L20: 0 | M20: 0 | N20: 0 | O20: 0 | P20: 0 | Q20: 0 | R20: 0 | S20: 0 | T20: 36.8 | U20: 0 | V20: 0 | W20: 36.8
A21: J. Morgan | B21: {=_xlfn.XLOOKUP(A21,'Player List'!$A$2:$A$177,'Player List'!$B$2:$C$177)} | C21: Back Row | D21: 80 | F21: 14 | G21: 21 | H21: 0 | I21: 8.6 | J21: 0 | K21: 0 | L21: 7 | M21: 0 | N21: 0 | O21: 0 | P21: 0 | Q21: 0 | R21: 0 | S21: 0 | T21: 50.6 | U21: 0 | V21: 0 | W21: 50.6
... A34: H. Keenan | B34: {=_xlfn.XLOOKUP(A34,'Player List'!$A$2:$A$177,'Player List'!$B$2:$C$177)} | C34: Back Three | D34: 80 | F34: 0 | G34: 0 | H34: 0 | I34: 17.2 | J34: 0 | K34: 0 | L34: 0 | M34: 0 | N34: 0 | O34: 0 | P34: 0 | Q34: 0 | R34: 0 | S34: 0 | T34: 17.2 | U34: 15 | V34: 0 | W34: 32.2
A35: J. Lowe | B35: {=_xlfn.XLOOKUP(A35,'Player List'!$A$2:$A$177,'Player List'!$B$2:$C$177)} | C35: Back Three | D35: 80 | F35: 4 | G35: ='Round 1 Data'!G35*'Round 1 Points'!M$2 | H35: ='Round 1 Data'!H35*'Round 1 Points'!N$2 | I35: ='Round 1 Data'!I35*'Round 1 Points'!O$2 | J35: ='Round 1 Data'!J35*'Round 1 Points'!P$2 | K35: ='Round 1 Data'!K35*'Round 1 Points'!Q$2 | L35: ='Round 1 Data'!L35*'Round 1 Points'!R$2 | M35: ='Round 1 Data'!M35*'Round 1 Points'!S$2 | N35: ='Round 1 Data'!N35*'Round 1 Points'!T$2 | ... S35: ='Round 1 Data'!S35*'Round 1 Points'!Y$2 | T35: =SUM(F35:S35) | U35: ='Round 1 Data'!U35*'Round 1 Points'!$Z$2 | V35: =IF('Round 1 Data'!D35='Round 1 Points'!$K$1,'Round 1 Points'!$K$2*D35/80,0) | W35: =SUM(T35:V35)
A36: B. Aki | B36: {=_xlfn.XLOOKUP(A36,'Player List'!$A$2:$A$177,'Player List'!$B$2:$C$177)} | C36: Centre | D36: 20 | F36: 4 | G36: 0 | H36: 7 | I36: 22.4 | J36: 0 | K36: 0 | L36: 7 | M36: 15 | N36: 0 | O36: 0 | P36: 0 | Q36: 0 | R36: 0 | S36: 0 | T36: 55.4 | U36: 0 | V36: 0 | W36: 55.4
A37: S. McCloskey | B37: {=_xlfn.XLOOKUP(A37,'Player List'!$A$2:$A$177,'Player List'!$B$2:$C$177)} | C37: Centre | D37: 60 | F37: 2 | G37: 0 | H37: 0 | I37: 2.6 | J37: 0 | K37: 0 | L37: 7 | M37: 0 | N37: 0 | O37: 0 | P37: 0 | Q37: 0 | R37: 0 | S37: 0 | T37: 11.6 | U37: 0 | V37: 0 | W37: 11.6
A38: G. Ringrose | B38: {=_xlfn.XLOOKUP(A38,'Player List'!$A$2:$A$177,'Player List'!$B$2:$C$177)} | C38: Centre | D38: 80 | F38: 7 | G38: 0 | H38: 0 | I38: 13.2 | J38: 0 | K38: 0 | L38: 0 | M38: 0 | N38: 0 | O38: 0 | P38: 0 | Q38: 0 | R38: 0 | S38: 0 | T38: 20.2 | U38: 0 | V38: 0 | W38: 20.2
A39: R. Byrne | B39: {=_xlfn.XLOOKUP(A39,'Player List'!$A$2:$A$177,'Player List'!$B$2:$C$177)} | C39: Fly Half | D39: 12 | F39: 10 | G39: 0 | H39: 0 | I39: 9.8 | J39: 0 | K39: 0 | L39: 0 | M39: 0 | N39: 0 | O39: 0 | P39: 0 | Q39: 0 | R39: 0 | S39: 0 | T39: 19.8 | U39: 0 | V39: 0 | W39: 19.8
A40: J. Sexton | B40: {=_xlfn.XLOOKUP(A40,'Player List'!$A$2:$A$177,'Player List'!$B$2:$C$177)} | C40: Fly Half | D40: 68 | F40: 0 | G40: 0 | H40: 0 | I40: 2.2 | J40: 0 | K40: 0 | L40: 0 | M40: 0 | N40: 0 | O40: 2 | P40: 0 | Q40: 0 | R40: 0 | S40: 0 | T40: 4.2 | U40: 0 | V40: 0 | W40: 4.2
A41: C. Casey | B41: {=_xlfn.XLOOKUP(A41,'Player List'!$A$2:$A$177,'Player List'!$B$2:$C$177)} | C41: Scrum Half | D41: 16 | F41: 7 | G41: 0 | H41: 0 | I41: 6 | J41: 0 | K41: 0 | L41: 7 | M41: 0 | N41: 0 | O41: 6 | P41: 10 | Q41: 0 | R41: 0 | S41: 0 | T41: 36 | U41: 0 | V41: 0 | W41: 36
A42: C. Murray | B42: {=_xlfn.XLOOKUP(A42,'Player List'!$A$2:$A$177,'Player List'!$B$2:$C$177)} | C42: Scrum Half | D42: 64 | F42: 1 | G42: 0 | H42: 0 | I42: 0.2 | J42: 0 | K42: 0 | L42: 0 | M42: 0 | N42: 7 | O42: 0 | P42: 0 | Q42: 0 | R42: 0 | S42: 0 | T42: 8.2 | U42: 0 | V42: 0 | W42: 8.2
A43: J. Conan | B43: {=_xlfn.XLOOKUP(A43,'Player List'!$A$2:$A$177,'Player List'!$B$2:$C$177)} | C43: Back Row | D43: 20 | F43: 1 | G43: 7 | H43: 7 | I43: 2.4 | J43: 0 | K43: 0 | L43: 0 | M43: 0 | N43: 7 | O43: 0 | P43: 0 | Q43: 0 | R43: 0 | S43: 0 | T43: 24.4 | U43: 0 | V43: 0 | W43: 24.4
A44: C. Doris | B44: {=_xlfn.XLOOKUP(A44,'Player List'!$A$2:$A$177,'Player List'!$B$2:$C$177)} | C44: Back Row | D44: 80 | F44: 4 | G44: 0 | H44: 0 | I44: 1.4 | J44: 0 | K44: 0 | L44: 7 | M44: 0 | N44: 0 | O44: 0 | P44: 0 | Q44: 0 | R44: 0 | S44: 0 | T44: 12.4 | U44: 0 | V44: 0 | W44: 12.4
A45: P. O'Mahony | B45: {=_xlfn.XLOOKUP(A45,'Player List'!$A$2:$A$177,'Player List'!$B$2:$C$177)} | C45: Back Row | D45: 60 | F45: 17 | G45: 7 | H45: 0 | I45: 9 | J45: 0 | K45: 0 | L45: 7 | M45: 15 | N45: 0 | O45: 0 | P45: 0 | Q45: 0 | R45: 0 | S45: 0 | T45: 55 | U45: 0 | V45: 0 | W45: 55
A46: J. van der Flier | B46: {=_xlfn.XLOOKUP(A46,'Player List'!$A$2:$A$177,'Player List'!$B$2:$C$177)} | C46: Back Row | D46: 80 | F46: 4 | G46: 7 | H46: 0 | I46: 5 | J46: 0 | K46: 0 | L46: 0 | M46: 0 | N46: 0 | O46: 0 | P46: 0 | Q46: 0 | R46: 0 | S46: 0 | T46: 16 | U46: 0 | V46: 0 | W46: 16
A47: T. Beirne | B47: {=_xlfn.XLOOKUP(A47,'Player List'!$A$2:$A$177,'Player List'!$B$2:$C$177)} | C47: Second Row | D47: 54 | F47: 12 | G47: 7 | H47: 7 | I47: 6.2 | J47: 0 | K47: 0 | L47: 0 | M47: 15 | N47: 0 | O47: 0 | P47: 0 | Q47: 0 | R47: 0 | S47: 0 | T47: 47.2 | U47: 0 | V47: 0 | W47: 47.2
... A144: J. Marchand | B144: {=_xlfn.XLOOKUP(A144,'Player List'!$A$2:$A$177,'Player List'!$B$2:$C$177)} | C144: Hooker | D144: 61 | F144: 4 | G144: 7 | H144: 0 | I144: 0 | J144: 0 | K144: 0 | L144: 0 | M144: 0 | N144: 0 | O144: 0 | P144: 0 | Q144: 0 | R144: 0 | S144: 0 | T144: 11 | U144: 0 | V144: 0 | W144: 11

Sheet Round 2 Points
K1: Win | L1: Tackles | M1: Dominant Tackles | N1: Line Breaks | O1: Metres Carried | P1: 50-22 | Q1: Lineout Steal | R1: Breakdown Steal | S1: Try | T1: Assists | U1: Conversion | V1: Penalty | W1: Drop Goal | X1: Yellow Card | Y1: Red Card | Z1: MOM
B2: Scotland | C2: Win | E2: Ireland | F2: 32 | G2: 19 | H2: France | J2: Points | K2: 8 | L2: 1 | M2: 7 | N2: 7 | O2: 0.2 | P2: 10 | Q2: 7 | R2: 7 | S2: 15 | T2: 7 | U2: 2 | V2: 5 | W2: 7 | X2: -5 | Y2: -10 | Z2: 15
B3: Wales | C3: Loss | E3: Scotland | F3: 35 | G3: 7 | H3: Wales
B4: Ireland | C4: Win | E4: England | F4: 31 | G4: 14 | H4: Italy
B5: England | C5: Win
B6: France | C6: Loss
B7: Italy | C7: Loss
A9: Name | B9: Nation | C9: Position | D9: Time Played | F9: Tackles | G9: Dominant Tackles | H9: Line Breaks | I9: Metres Carried | J9: 50-22 | K9: Lineout Steal | L9: Breakdown Steal | M9: Try | N9: Assists | O9: Conversion | P9: Penalty | Q9: Drop Goal | R9: Yellow Card | S9: Red Card | T9: Game Total | U9: MoM | V9: Win Points | W9: Total Points
A10: M. Hansen | B10: {=_xlfn.XLOOKUP(A10,'Player List'!$A$2:$A$177,'Player List'!$B$2:$C$177)} | C10: Back Three | D10: 80 | F10: 5 | G10: 0 | H10: 0 | I10: 12.6 | J10: 0 | K10: 0 | L10: 0 | M10: 0 | N10: 0 | O10: 0 | P10: 0 | Q10: 0 | R10: 0 | S10: 0 | T10: 17.6 | U10: 0 | V10: 0 | W10: 17.6
A11: H. Keenan | B11: {=_xlfn.XLOOKUP(A11,'Player List'!$A$2:$A$177,'Player List'!$B$2:$C$177)} | C11: Back Three | D11: 80 | F11: 3 | G11: 7 | H11: 14 | I11: 41 | J11: 10 | K11: 0 | L11: 0 | M11: 15 | N11: 0 | O11: 0 | P11: 0 | Q11: 0 | R11: 0 | S11: 0 | T11: 90 | U11: 0 | V11: 0 | W11: 90
A12: J. Lowe | B12: {=_xlfn.XLOOKUP(A12,'Player List'!$A$2:$A$177,'Player List'!$B$2:$C$177)} | C12: Back Three | D12: 80 | F12: 4 | G12: 0 | H12: 7 | I12: 18.8 | J12: 0 | K12: 0 | L12: 0 | M12: 15 | N12: 0 | O12: 0 | P12: 0 | Q12: 0 | R12: 0 | S12: 0 | T12: 44.8 | U12: 0 | V12: 0 | W12: 44.8
A13: B. Aki | B13: {=_xlfn.XLOOKUP(A13,'Player List'!$A$2:$A$177,'Player List'!$B$2:$C$177)} | C13: Centre | D13: 14 | F13: 3 | G13: 0 | H13: 0 | I13: 5 | J13: 0 | K13: 0 | L13: 0 | M13: 0 | N13: 0 | O13: 0 | P13: 0 | Q13: 0 | R13: 0 | S13: 0 | T13: 8 | U13: 0 | V13: 0 | W13: 8
A14: S. McCloskey | B14: {=_xlfn.XLOOKUP(A14,'Player List'!$A$2:$A$177,'Player List'!$B$2:$C$177)} | C14: Centre | D14: 66 | F14: 3 | G14: 0 | H14: 0 | I14: 13.8 | J14: 0 | K14: 0 | L14: 7 | M14: 0 | N14: 0 | O14: 0 | P14: 0 | Q14: 0 | R14: 0 | S14: 0 | T14: 23.8 | U14: 0 | V14: 0 | W14: 23.8
A15: G. Ringrose | B15: {=_xlfn.XLOOKUP(A15,'Player List'!$A$2:$A$177,'Player List'!$B$2:$C$177)} | C15: Centre | D15: 80 | F15: 9 | G15: 7 | H15: 7 | I15: 12.8 | J15: 0 | K15: 0 | L15: 0 | M15: 15 | N15: 7 | O15: 0 | P15: 0 | Q15: 0 | R15: 0 | S15: 0 | T15: 57.8 | U15: 0 | V15: 0 | W15: 57.8
A16: R. Byrne | B16: {=_xlfn.XLOOKUP(A16,'Player List'!$A$2:$A$177,'Player List'!$B$2:$C$177)} | C16: Fly Half | D16: 32 | F16: 3 | G16: 0 | H16: 0 | I16: 2 | J16: 0 | K16: 0 | L16: 0 | M16: 0 | N16: 0 | O16: 2 | P16: 5 | Q16: 0 | R16: 0 | S16: 0 | T16: 12 | U16: 0 | V16: 0 | W16: 12
A17: J. Sexton | B17: {=_xlfn.XLOOKUP(A17,'Player List'!$A$2:$A$177,'Player List'!$B$2:$C$177)} | C17: Fly Half | D17: 48 | F17: 3 | G17: 0 | H17: 14 | I17: 16 | J17: 0 | K17: 0 | L17: 0 | M17: 0 | N17: 0 | O17: 4 | P17: 5 | Q17: 0 | R17: 0 | S17: 0 | T17: 42 | U17: 0 | V17: 0 | W17: 42
A18: C. Casey | B18: {=_xlfn.XLOOKUP(A18,'Player List'!$A$2:$A$177,'Player List'!$B$2:$C$177)} | C18: Scrum Half | D18: 24 | F18: 1 | G18: 0 | H18: 0 | I18: 2.8 | J18: 0 | K18: 0 | L18: 0 | M18: 0 | N18: 0 | O18: 0 | P18: 0 | Q18: 0 | R18: 0 | S18: 0 | T18: 3.8 | U18: 0 | V18: 0 | W18: 3.8
A19: C. Murray | B19: {=_xlfn.XLOOKUP(A19,'Player List'!$A$2:$A$177,'Player List'!$B$2:$C$177)} | C19: Scrum Half | D19: 56 | F19: 3 | G19: 0 | H19: 0 | I19: 2.2 | J19: 0 | K19: 0 | L19: 0 | M19: 0 | N19: 0 | O19: 0 | P19: 0 | Q19: 0 | R19: 0 | S19: 0 | T19: 5.2 | U19: 0 | V19: 0 | W19: 5.2
A20: J. Conan | B20: {=_xlfn.XLOOKUP(A20,'Player List'!$A$2:$A$177,'Player List'!$B$2:$C$177)} | C20: Back Row | D20: 24 | F20: 2 | G20: 0 | H20: 0 | I20: 4.4 | J20: 0 | K20: 0 | L20: 0 | M20: 0 | N20: 0 | O20: 0 | P20: 0 | Q20: 0 | R20: 0 | S20: 0 | T20: 6.4 | U20: 0 | V20: 0 | W20: 6.4
A21: C. Doris | B21: {=_xlfn.XLOOKUP(A21,'Player List'!$A$2:$A$177,'Player List'!$B$2:$C$177)} | C21: Back Row | D21: 80 | F21: 6 | G21: 0 | H21: 0 | I21: 23.4 | J21: 0 | K21: 0 | L21: 7 | M21: 0 | N21: 7 | O21: 0 | P21: 0 | Q21: 0 | R21: 0 | S21: 0 | T21: 43.4 | U21: 15 | V21: 0 | W21: 58.4
... A146: G. Nicotera | B146: {=_xlfn.XLOOKUP(A146,'Player List'!$A$2:$A$177,'Player List'!$B$2:$C$177)} | C146: Hooker | D146: 61 | F146: 13 | G146: 0 | H146: 0 | I146: 8.6 | J146: 0 | K146: 0 | L146: 0 | M146: 0 | N146: 0 | O146: 0 | P146: 0 | Q146: 0 | R146: 0 | S146: 0 | T146: 21.6 | U146: 0 | V146: 0 | W146: 21.6

Sheet Round 3 Points
K1: Win | L1: Tackles | M1: Dominant Tackles | N1: Line Breaks | O1: Metres Carried | P1: 50-22 | Q1: Lineout Steal | R1: Breakdown Steal | S1: Try | T1: Assists | U1: Conversion | V1: Penalty | W1: Drop Goal | X1: Yellow Card | Y1: Red Card | Z1: MOM
B2: Scotland | C2: Loss | E2: Italy | F2: 20 | G2: 34 | H2: Ireland | J2: Points | K2: 8 | L2: 1 | M2: 7 | N2: 7 | O2: 0.2 | P2: 10 | Q2: 7 | R2: 7 | S2: 15 | T2: 7 | U2: 2 | V2: 5 | W2: 7 | X2: -5 | Y2: -10 | Z2: 15
B3: Wales | C3: Loss | E3: Wales | F3: 10 | G3: 20 | H3: England
B4: Ireland | C4: Win | E4: France | F4: 32 | G4: 21 | H4: Scotland
B5: England | C5: Win
B6: France | C6: Win
B7: Italy | C7: Loss
A9: Name | B9: Nation | C9: Position | D9: Time Played | F9: Tackles | G9: Dominant Tackles | H9: Line Breaks | I9: Metres Carried | J9: 50-22 | K9: Lineout Steal | L9: Breakdown Steal | M9: Try | N9: Assists | O9: Conversion | P9: Penalty | Q9: Drop Goal | R9: Yellow Card | S9: Red Card | T9: Game Total | U9: MoM | V9: Win Points | W9: Total Points
A10: M. Hansen | B10: {=_xlfn.XLOOKUP(A10,'Player List'!$A$2:$A$177,'Player List'!$B$2:$C$177)} | C10: Back Three | D10: 80 | F10: 2 | G10: 0 | H10: 21 | I10: 15 | J10: 0 | K10: 0 | L10: 7 | M10: 30 | N10: 0 | O10: 0 | P10: 0 | Q10: 0 | R10: 0 | S10: 0 | T10: 75 | U10: 15 | V10: 0 | W10: 90
A11: H. Keenan | B11: {=_xlfn.XLOOKUP(A11,'Player List'!$A$2:$A$177,'Player List'!$B$2:$C$177)} | C11: Back Three | D11: 80 | F11: 3 | G11: 7 | H11: 0 | I11: 24.8 | J11: 0 | K11: 0 | L11: 0 | M11: 15 | N11: 0 | O11: 0 | P11: 0 | Q11: 0 | R11: 0 | S11: 0 | T11: 49.8 | U11: 0 | V11: 0 | W11: 49.8
A12: J. Lowe | B12: {=_xlfn.XLOOKUP(A12,'Player List'!$A$2:$A$177,'Player List'!$B$2:$C$177)} | C12: Back Three | D12: 80 | F12: 1 | G12: 14 | H12: 28 | I12: 26.2 | J12: 0 | K12: 0 | L12: 0 | M12: 0 | N12: 14 | O12: 0 | P12: 0 | Q12: 0 | R12: 0 | S12: 0 | T12: 83.2 | U12: 0 | V12: 0 | W12: 83.2
A13: J. O'Brien | B13: {=_xlfn.XLOOKUP(A13,'Player List'!$A$2:$A$177,'Player List'!$B$2:$C$177)} | C13: Back Three | D13: 8 | F13: 0 | G13: 0 | H13: 0 | I13: 0 | J13: 0 | K13: 0 | L13: 0 | M13: 0 | N13: 0 | O13: 0 | P13: 0 | Q13: 0 | R13: 0 | S13: 0 | T13: 0 | U13: 0 | V13: 0 | W13: 0
A14: B. Aki | B14: {=_xlfn.XLOOKUP(A14,'Player List'!$A$2:$A$177,'Player List'!$B$2:$C$177)} | C14: Centre | D14: 80 | F14: 7 | G14: 0 | H14: 7 | I14: 21.4 | J14: 0 | K14: 0 | L14: 7 | M14: 15 | N14: 7 | O14: 0 | P14: 0 | Q14: 0 | R14: 0 | S14: 0 | T14: 64.4 | U14: 0 | V14: 0 | W14: 64.4
A15: S. McCloskey | B15: {=_xlfn.XLOOKUP(A15,'Player List'!$A$2:$A$177,'Player List'!$B$2:$C$177)} | C15: Centre | D15: 72 | F15: 14 | G15: 0 | H15: 0 | I15: 13.8 | J15: 0 | K15: 0 | L15: 0 | M15: 0 | N15: 7 | O15: 0 | P15: 0 | Q15: 0 | R15: 0 | S15: 0 | T15: 34.8 | U15: 0 | V15: 0 | W15: 34.8
A16: R. Byrne | B16: {=_xlfn.XLOOKUP(A16,'Player List'!$A$2:$A$177,'Player List'!$B$2:$C$177)} | C16: Fly Half | D16: 78 | F16: 4 | G16: 0 | H16: 0 | I16: 2.4 | J16: 0 | K16: 0 | L16: 0 | M16: 0 | N16: 0 | O16: 6 | P16: 5 | Q16: 0 | R16: 0 | S16: 0 | T16: 17.4 | U16: 0 | V16: 0 | W16: 17.4
A17: J. Crowley | B17: {=_xlfn.XLOOKUP(A17,'Player List'!$A$2:$A$177,'Player List'!$B$2:$C$177)} | C17: Fly Half | D17: 2 | F17: 2 | G17: 0 | H17: 0 | I17: 0 | J17: 0 | K17: 0 | L17: 0 | M17: 0 | N17: 0 | O17: 0 | P17: 0 | Q17: 0 | R17: 0 | S17: 0 | T17: 2 | U17: 0 | V17: 0 | W17: 2
A18: C. Casey | B18: {=_xlfn.XLOOKUP(A18,'Player List'!$A$2:$A$177,'Player List'!$B$2:$C$177)} | C18: Scrum Half | D18: 65 | F18: 2 | G18: 0 | H18: 0 | I18: 0.8 | J18: 0 | K18: 0 | L18: 0 | M18: 0 | N18: 0 | O18: 0 | P18: 0 | Q18: 0 | R18: 0 | S18: 0 | T18: 2.8 | U18: 0 | V18: 0 | W18: 2.8
A19: C. Murray | B19: {=_xlfn.XLOOKUP(A19,'Player List'!$A$2:$A$177,'Player List'!$B$2:$C$177)} | C19: Scrum Half | D19: 15 | F19: 1 | G19: 0 | H19: 0 | I19: 1.2 | J19: 0 | K19: 0 | L19: 0 | M19: 0 | N19: 7 | O19: 0 | P19: 0 | Q19: 0 | R19: 0 | S19: 0 | T19: 9.2 | U19: 0 | V19: 0 | W19: 9.2
A20: J. Conan | B20: {=_xlfn.XLOOKUP(A20,'Player List'!$A$2:$A$177,'Player List'!$B$2:$C$177)} | C20: Back Row | D20: 56 | F20: 4 | G20: 0 | H20: 0 | I20: 8.4 | J20: 0 | K20: 0 | L20: 0 | M20: 0 | N20: 0 | O20: 0 | P20: 0 | Q20: 0 | R20: 0 | S20: 0 | T20: 12.4 | U20: 0 | V20: 0 | W20: 12.4
A21: C. Doris | B21: {=_xlfn.XLOOKUP(A21,'Player List'!$A$2:$A$177,'Player List'!$B$2:$C$177)} | C21: Back Row | D21: 80 | F21: 10 | G21: 7 | H21: 0 | I21: 8.6 | J21: 0 | K21: 0 | L21: 7 | M21: 0 | N21: 0 | O21: 0 | P21: 0 | Q21: 0 | R21: 0 | S21: 0 | T21: 32.6 | U21: 0 | V21: 0 | W21: 32.6
... A145: G. Turner | B145: {=_xlfn.XLOOKUP(A145,'Player List'!$A$2:$A$177,'Player List'!$B$2:$C$177)} | C145: Hooker | D145: 63 | F145: 5 | G145: 0 | H145: 0 | I145: 9.4 | J145: 0 | K145: 0 | L145: 0 | M145: 0 | N145: 0 | O145: 0 | P145: 0 | Q145: 0 | R145: 0 | S145: 0 | T145: 14.4 | U145: 0 | V145: 0 | W145: 14.4

Sheet Round 4 Points
K1: Win | L1: Tackles | M1: Dominant Tackles | N1: Line Breaks | O1: Metres Carried | P1: 50-22 | Q1: Lineout Steal | R1: Breakdown Steal | S1: Try | T1: Assists | U1: Conversion | V1: Penalty | W1: Drop Goal | X1: Yellow Card | Y1: Red Card | Z1: MOM
B2: Scotland | C2: Loss | E2: Italy | F2: 17 | G2: 29 | H2: Wales | J2: Points | K2: 8 | L2: 1 | M2: 7 | N2: 7 | O2: 0.2 | P2: 10 | Q2: 7 | R2: 7 | S2: 15 | T2: 7 | U2: 2 | V2: 5 | W2: 7 | X2: -5 | Y2: -10 | Z2: 15
B3: Wales | C3: Win | E3: England | F3: 53 | G3: 10 | H3: France
B4: Ireland | C4: Win | E4: Scotland | F4: 7 | G4: 22 | H4: Ireland
B5: England | C5: Loss
B6: France | C6: Win
B7: Italy | C7: Loss
A9: Name | B9: Nation | C9: Position | D9: Time Played | F9: Tackles | G9: Dominant Tackles | H9: Line Breaks | I9: Metres Carried | J9: 50-22 | K9: Lineout Steal | L9: Breakdown Steal | M9: Try | N9: Assists | O9: Conversion | P9: Penalty | Q9: Drop Goal | R9: Yellow Card | S9: Red Card | T9: Game Total | U9: MoM | V9: Win Points | W9: Total Points
A10: P. Bruno | B10: {=_xlfn.XLOOKUP(A10,'Player List'!$A$2:$A$177,'Player List'!$B$2:$C$177)} | C10: Back Three | D10: 69 | F10: 2 | G10: 0 | H10: 0 | I10: 5.8 | J10: 0 | K10: 0 | L10: 0 | M10: 0 | N10: 7 | O10: 0 | P10: 0 | Q10: 0 | R10: -5 | S10: 0 | T10: 9.8 | U10: 0 | V10: 0 | W10: 9.8
A11: A. Fusco | B11: {=_xlfn.XLOOKUP(A11,'Player List'!$A$2:$A$177,'Player List'!$B$2:$C$177)} | C11: Back Three | D11: 24 | F11: 0 | G11: 0 | H11: 7 | I11: 10 | J11: 0 | K11: 0 | L11: 0 | M11: 0 | N11: 0 | O11: 0 | P11: 0 | Q11: 0 | R11: 0 | S11: 0 | T11: 17 | U11: 0 | V11: 0 | W11: 17
A12: T. Menoncello | B12: {=_xlfn.XLOOKUP(A12,'Player List'!$A$2:$A$177,'Player List'!$B$2:$C$177)} | C12: Back Three | D12: 59 | F12: 7 | G12: 7 | H12: 7 | I12: 15.8 | J12: 0 | K12: 0 | L12: 0 | M12: 0 | N12: 0 | O12: 0 | P12: 0 | Q12: 0 | R12: 0 | S12: 0 | T12: 36.8 | U12: 0 | V12: 0 | W12: 36.8
A13: E. Padovani | B13: {=_xlfn.XLOOKUP(A13,'Player List'!$A$2:$A$177,'Player List'!$B$2:$C$177)} | C13: Back Three | D13: 80 | F13: 1 | G13: 7 | H13: 7 | I13: 10.2 | J13: 0 | K13: 0 | L13: 0 | M13: 0 | N13: 0 | O13: 0 | P13: 0 | Q13: 0 | R13: 0 | S13: 0 | T13: 25.2 | U13: 0 | V13: 0 | W13: 25.2
A14: J. Brex | B14: {=_xlfn.XLOOKUP(A14,'Player List'!$A$2:$A$177,'Player List'!$B$2:$C$177)} | C14: Centre | D14: 80 | F14: 2 | G14: 0 | H14: 7 | I14: 18 | J14: 0 | K14: 0 | L14: 0 | M14: 15 | N14: 0 | O14: 0 | P14: 0 | Q14: 0 | R14: 0 | S14: 0 | T14: 42 | U14: 0 | V14: 0 | W14: 42
A15: L. Morisi | B15: {=_xlfn.XLOOKUP(A15,'Player List'!$A$2:$A$177,'Player List'!$B$2:$C$177)} | C15: Centre | D15: 21 | F15: 0 | G15: 0 | H15: 0 | I15: 4.8 | J15: 0 | K15: 0 | L15: 0 | M15: 0 | N15: 0 | O15: 0 | P15: 0 | Q15: 0 | R15: 0 | S15: 0 | T15: 4.8 | U15: 0 | V15: 0 | W15: 4.8
A16: T. Allan | B16: {=_xlfn.XLOOKUP(A16,'Player List'!$A$2:$A$177,'Player List'!$B$2:$C$177)} | C16: Fly Half | D16: 80 | F16: 0 | G16: 0 | H16: 21 | I16: 15.6 | J16: 0 | K16: 0 | L16: 0 | M16: 0 | N16: 7 | O16: 4 | P16: 5 | Q16: 0 | R16: 0 | S16: 0 | T16: 52.6 | U16: 0 | V16: 0 | W16: 52.6
A17: P. Garbisi | B17: {=_xlfn.XLOOKUP(A17,'Player List'!$A$2:$A$177,'Player List'!$B$2:$C$177)} | C17: Fly Half | D17: 80 | F17: 6 | G17: 0 | H17: 7 | I17: 7.4 | J17: 0 | K17: 0 | L17: 0 | M17: 0 | N17: 0 | O17: 0 | P17: 0 | Q17: 0 | R17: 0 | S17: 0 | T17: 20.4 | U17: 0 | V17: 0 | W17: 20.4
A18: S. Varney | B18: {=_xlfn.XLOOKUP(A18,'Player List'!$A$2:$A$177,'Player List'!$B$2:$C$177)} | C18: Scrum Half | D18: 56 | F18: 3 | G18: 0 | H18: 0 | I18: 7.6 | J18: 0 | K18: 0 | L18: 0 | M18: 0 | N18: 0 | O18: 0 | P18: 0 | Q18: 0 | R18: 0 | S18: 0 | T18: 10.6 | U18: 0 | V18: 0 | W18: 10.6
A19: E. Iachizzi | B19: {=_xlfn.XLOOKUP(A19,'Player List'!$A$2:$A$177,'Player List'!$B$2:$C$177)} | C19: Back Row | D19: 20 | F19: 1 | G19: 0 | H19: 7 | I19: 5.6 | J19: 0 | K19: 0 | L19: 7 | M19: 0 | N19: 0 | O19: 0 | P19: 0 | Q19: 0 | R19: 0 | S19: 0 | T19: 20.6 | U19: 0 | V19: 0 | W19: 20.6
A20: M. Lamaro | B20: {=_xlfn.XLOOKUP(A20,'Player List'!$A$2:$A$177,'Player List'!$B$2:$C$177)} | C20: Back Row | D20: 77 | F20: 7 | G20: 0 | H20: 0 | I20: 4.8 | J20: 0 | K20: 0 | L20: 0 | M20: 0 | N20: 0 | O20: 0 | P20: 0 | Q20: 0 | R20: 0 | S20: 0 | T20: 11.8 | U20: 0 | V20: 0 | W20: 11.8
A21: S. Negri | B21: {=_xlfn.XLOOKUP(A21,'Player List'!$A$2:$A$177,'Player List'!$B$2:$C$177)} | C21: Back Row | D21: 52 | F21: 5 | G21: 0 | H21: 7 | I21: 10 | J21: 0 | K21: 0 | L21: 0 | M21: 15 | N21: 0 | O21: 0 | P21: 0 | Q21: 0 | R21: 0 | S21: 0 | T21: 37 | U21: 0 | V21: 0 | W21: 37
... A147: D. Sheehan | B147: {=_xlfn.XLOOKUP(A147,'Player List'!$A$2:$A$177,'Player List'!$B$2:$C$177)} | C147: Hooker | D147: 18 | F147: 4 | G147: 0 | H147: 0 | I147: 0 | J147: 0 | K147: 0 | L147: 0 | M147: 0 | N147: 0 | O147: 0 | P147: 0 | Q147: 0 | R147: 0 | S147: 0 | T147: 4 | U147: 0 | V147: 0 | W147: 4

Sheet Summary Points
B2: Win | C2: Tackles | D2: Dominant Tackles | E2: Line Breaks | F2: Metres Carried | G2: 50-22 | H2: Lineout Steal | I2: Breakdown Steal | J2: Try | K2: Assists | L2: Conversion | M2: Penalty | N2: Drop Goal | O2: Yellow Card | P2: Red Card | Q2: MOM
A3: Points | B3: 8 | C3: 1 | D3: 7 | E3: 7 | F3: 0.2 | G3: 10 | H3: 7 | I3: 7 | J3: 15 | K3: 7 | L3: 2 | M3: 5 | N3: 7 | O3: -5 | P3: -10 | Q3: 15
E5: Average
A6: Name | B6: Nation | C6: Position | D6: Games Played | E6: Time Played | F6: Tackles | G6: Dominant Tackles | H6: Line Breaks | I6: Metres Carried | J6: 50-22 | K6: Lineout Steal | L6: Breakdown Steal | M6: Try | N6: Assists | O6: Conversion | P6: Penalty | Q6: Drop Goal | R6: Yellow Card | S6: Red Card | T6: Game Total | U6: MOM | V6: Win Points | W6: Total Average Points
A7: J. Adams | B7: Wales | C7: Back Three | D7: 4 | E7: 61 | F7: 3.75 | G7: 8.75 | H7: 1.75 | I7: 5.25 | J7: 0 | K7: 0 | L7: 1.75 | M7: 0 | N7: 0 | O7: 0 | P7: 0 | Q7: 0 | R7: 0 | S7: 0 | T7: 21.25 | U7: 0 | V7: 0 | W7: 21.25
A8: A. Cuthbert | B8: Wales | C8: Back Three | D8: 2 | E8: 20 | F8: 1 | G8: 0 | H8: 0 | I8: 7.5 | J8: 0 | K8: 0 | L8: 0 | M8: 0 | N8: 0 | O8: 0 | P8: 0 | Q8: 0 | R8: 0 | S8: 0 | T8: 8.5 | U8: 0 | V8: 0 | W8: 8.5
A9: R. Dyer | B9: Wales | C9: Back Three | D9: 3 | E9: 76 | F9: 4.3333 | G9: 2.3331 | H9: 9.3331 | I9: 14.4 | J9: 0 | K9: 0 | L9: 0 | M9: 4.9995 | N9: 0 | O9: 0 | P9: 0 | Q9: 0 | R9: 0 | S9: 0 | T9: 35.4 | U9: 0 | V9: 0 | W9: 35.4
A10: L. Williams | B10: Wales | C10: Back Three | D10: 3 | E10: 67 | F10: 4 | G10: 0 | H10: 7 | I10: 15.9333 | J10: 0 | K10: 0 | L10: 4.6669 | M10: 10.0005 | N10: 0 | O10: 0 | P10: 0 | Q10: 0 | R10: -3.3335 | S10: 0 | T10: 38.2667 | U10: 0 | V10: 0 | W10: 38.2667
A11: J. Hawkins | B11: Wales | C11: Centre | D11: 4 | E11: 80 | F11: 5.5 | G11: 3.5 | H11: 1.75 | I11: 13.85 | J11: 0 | K11: 0 | L11: 0 | M11: 0 | N11: 0 | O11: 0 | P11: 0 | Q11: 0 | R11: 0 | S11: 0 | T11: 24.6 | U11: 0 | V11: 0 | W11: 24.6
A12: G. North | B12: Wales | C12: Centre | D12: 3 | E12: 57 | F12: 2.3333 | G12: 2.3331 | H12: 0 | I12: 7.2667 | J12: 0 | K12: 0 | L12: 0 | M12: 0 | N12: 0 | O12: 0 | P12: 0 | Q12: 0 | R12: 0 | S12: 0 | T12: 11.9333 | U12: 0 | V12: 0 | W12: 11.9333
